WARNING:django.request:Not Found: /favicon.ico
WARNING:django.request:Not Found: /favicon.ico
ERROR:django.security.DisallowedHost:Invalid HTTP_HOST header: '160.251.51.99:8080'. You may need to add '160.251.51.99' to ALLOWED_HOSTS.
WARNING:django.request:Bad Request: /
ERROR:django.security.DisallowedHost:Invalid HTTP_HOST header: '160.251.51.99:8080'. You may need to add '160.251.51.99' to ALLOWED_HOSTS.
WARNING:django.request:Bad Request: /favicon.ico
INFO:django.utils.autoreload:/Anty/main/main/settings.py changed, reloading.
WARNING:django.request:Not Found: /favicon.ico
INFO:django.utils.autoreload:/Anty/main/Anty/views/listing.py changed, reloading.
WARNING:django.request:Not Found: /favicon.ico
ERROR:django.request:Internal Server Error: /select_category/
Traceback (most recent call last):
  File "/usr/local/lib/python3.8/dist-packages/django/core/handlers/exception.py", line 47, in inner
    response = get_response(request)
  File "/usr/local/lib/python3.8/dist-packages/django/core/handlers/base.py", line 181, in _get_response
    response = wrapped_callback(request, *callback_args, **callback_kwargs)
  File "/usr/local/lib/python3.8/dist-packages/django/contrib/auth/decorators.py", line 21, in _wrapped_view
    return view_func(request, *args, **kwargs)
  File "/Anty/main/Anty/views/listing.py", line 20, in select_category
    return render(request, tempalte_name, params)
NameError: name 'tempalte_name' is not defined
INFO:django.utils.autoreload:/Anty/main/Anty/views/listing.py changed, reloading.
WARNING:django.request:Not Found: /select_temp_product
WARNING:django.request:Not Found: /select_temp_product
ERROR:django.request:Internal Server Error: /select_temp/
Traceback (most recent call last):
  File "/usr/local/lib/python3.8/dist-packages/django/db/models/fields/__init__.py", line 1823, in get_prep_value
    return int(value)
ValueError: invalid literal for int() with base 10: 'undefined'

The above exception was the direct cause of the following exception:

Traceback (most recent call last):
  File "/usr/local/lib/python3.8/dist-packages/django/core/handlers/exception.py", line 47, in inner
    response = get_response(request)
  File "/usr/local/lib/python3.8/dist-packages/django/core/handlers/base.py", line 181, in _get_response
    response = wrapped_callback(request, *callback_args, **callback_kwargs)
  File "/usr/local/lib/python3.8/dist-packages/django/contrib/auth/decorators.py", line 21, in _wrapped_view
    return view_func(request, *args, **kwargs)
  File "/Anty/main/Anty/views/listing.py", line 29, in select_temp
    temp_product = Temp_used_product.objects.filter(brand=brand, gender=gender, category=category)
  File "/usr/local/lib/python3.8/dist-packages/django/db/models/manager.py", line 85, in manager_method
    return getattr(self.get_queryset(), name)(*args, **kwargs)
  File "/usr/local/lib/python3.8/dist-packages/django/db/models/query.py", line 941, in filter
    return self._filter_or_exclude(False, args, kwargs)
  File "/usr/local/lib/python3.8/dist-packages/django/db/models/query.py", line 961, in _filter_or_exclude
    clone._filter_or_exclude_inplace(negate, args, kwargs)
  File "/usr/local/lib/python3.8/dist-packages/django/db/models/query.py", line 968, in _filter_or_exclude_inplace
    self._query.add_q(Q(*args, **kwargs))
  File "/usr/local/lib/python3.8/dist-packages/django/db/models/sql/query.py", line 1393, in add_q
    clause, _ = self._add_q(q_object, self.used_aliases)
  File "/usr/local/lib/python3.8/dist-packages/django/db/models/sql/query.py", line 1412, in _add_q
    child_clause, needed_inner = self.build_filter(
  File "/usr/local/lib/python3.8/dist-packages/django/db/models/sql/query.py", line 1347, in build_filter
    condition = self.build_lookup(lookups, col, value)
  File "/usr/local/lib/python3.8/dist-packages/django/db/models/sql/query.py", line 1193, in build_lookup
    lookup = lookup_class(lhs, rhs)
  File "/usr/local/lib/python3.8/dist-packages/django/db/models/lookups.py", line 25, in __init__
    self.rhs = self.get_prep_lookup()
  File "/usr/local/lib/python3.8/dist-packages/django/db/models/fields/related_lookups.py", line 117, in get_prep_lookup
    self.rhs = target_field.get_prep_value(self.rhs)
  File "/usr/local/lib/python3.8/dist-packages/django/db/models/fields/__init__.py", line 1825, in get_prep_value
    raise e.__class__(
ValueError: Field 'id' expected a number but got 'undefined'.
ERROR:django.request:Internal Server Error: /select_temp/
Traceback (most recent call last):
  File "/usr/local/lib/python3.8/dist-packages/django/core/handlers/exception.py", line 47, in inner
    response = get_response(request)
  File "/usr/local/lib/python3.8/dist-packages/django/core/handlers/base.py", line 181, in _get_response
    response = wrapped_callback(request, *callback_args, **callback_kwargs)
  File "/usr/local/lib/python3.8/dist-packages/django/contrib/auth/decorators.py", line 21, in _wrapped_view
    return view_func(request, *args, **kwargs)
  File "/Anty/main/Anty/views/listing.py", line 33, in select_temp
    return render(request, template_name, params)
  File "/usr/local/lib/python3.8/dist-packages/django/shortcuts.py", line 19, in render
    content = loader.render_to_string(template_name, context, request, using=using)
  File "/usr/local/lib/python3.8/dist-packages/django/template/loader.py", line 61, in render_to_string
    template = get_template(template_name, using=using)
  File "/usr/local/lib/python3.8/dist-packages/django/template/loader.py", line 19, in get_template
    raise TemplateDoesNotExist(template_name, chain=chain)
django.template.exceptions.TemplateDoesNotExist: listing/select_temp.html
INFO:django.utils.autoreload:/Anty/main/main/urls.py changed, reloading.
INFO:django.utils.autoreload:/Anty/main/Anty/models.py changed, reloading.
INFO:django.utils.autoreload:/Anty/main/Anty/models.py changed, reloading.
INFO:django.utils.autoreload:/Anty/main/Anty/models.py changed, reloading.
WARNING:django.request:Not Found: /css/slick.css
WARNING:django.request:Not Found: /css/style.css
WARNING:django.request:Not Found: /css/slick-theme.css
WARNING:django.request:Not Found: /js/index.js
WARNING:django.request:Not Found: /js/slick.js
WARNING:django.request:Not Found: /css/style.css
WARNING:django.request:Not Found: /css/slick.css
WARNING:django.request:Not Found: /css/slick-theme.css
WARNING:django.request:Not Found: /js/slick.js
WARNING:django.request:Not Found: /js/index.js
WARNING:django.request:Not Found: /css/style.css
WARNING:django.request:Not Found: /css/slick-theme.css
WARNING:django.request:Not Found: /css/slick.css
WARNING:django.request:Not Found: /js/slick.js
WARNING:django.request:Not Found: /js/index.js
WARNING:django.request:Not Found: /css/slick.css
WARNING:django.request:Not Found: /css/slick-theme.css
WARNING:django.request:Not Found: /css/style.css
WARNING:django.request:Not Found: /js/index.js
WARNING:django.request:Not Found: /js/slick.js
WARNING:django.request:Not Found: /css/slick.css
WARNING:django.request:Not Found: /css/slick-theme.css
WARNING:django.request:Not Found: /css/style.css
WARNING:django.request:Not Found: /js/slick.js
WARNING:django.request:Not Found: /js/index.js
WARNING:django.request:Not Found: /js/slick.js
INFO:django.utils.autoreload:/Anty/main/Anty/views/listing.py changed, reloading.
WARNING:django.request:Not Found: /js/slick.js
WARNING:django.request:Not Found: /js/slick.js
WARNING:django.request:Not Found: /js/slick.js
WARNING:django.request:Not Found: /js/slick.js
WARNING:django.request:Not Found: /js/slick.js
WARNING:django.request:Not Found: /js/slick.js
WARNING:django.request:Not Found: /select_temp/item-input.html
WARNING:django.request:Not Found: /config/getuser
WARNING:django.request:Not Found: /select_temp/item-input.html
WARNING:django.request:Not Found: /js/slick.js
WARNING:django.request:Not Found: /js/slick.js
WARNING:django.request:Not Found: /js/slick.js
WARNING:django.request:Not Found: /js/slick.js
WARNING:django.request:Not Found: /system_api.php
WARNING:django.request:Not Found: /c/version.js
WARNING:django.request:Not Found: /streaming/clients_live.php
WARNING:django.request:Not Found: /stalker_portal/c/version.js
WARNING:django.request:Not Found: /stream/live.php
WARNING:django.request:Not Found: /flu/403.html
WARNING:django.request:Not Found: /favicon.ico
WARNING:django.request:Not Found: /select_category/item-select.html
WARNING:django.request:Not Found: /select_category/item-select.html
WARNING:django.request:Not Found: /js/slick.js
WARNING:django.request:Not Found: /js/slick.js
WARNING:django.request:Not Found: /favicon.ico
INFO:django.utils.autoreload:/Anty/main/Anty/views/listing.py changed, reloading.
WARNING:django.request:Not Found: /js/slick.js
WARNING:django.request:Not Found: /js/index.js
WARNING:django.request:Not Found: /js/slick.js
WARNING:django.request:Not Found: /js/index.js
WARNING:django.request:Not Found: /listing_detail
WARNING:django.request:Not Found: /js/slick.js
WARNING:django.request:Not Found: /js/index.js
WARNING:django.request:Not Found: /js/slick.js
WARNING:django.request:Not Found: /js/index.js
INFO:django.utils.autoreload:/Anty/main/main/urls.py changed, reloading.
INFO:django.utils.autoreload:/Anty/main/Anty/views/listing.py changed, reloading.
ERROR:django.request:Internal Server Error: /listing_detail/
Traceback (most recent call last):
  File "/usr/local/lib/python3.8/dist-packages/django/utils/datastructures.py", line 76, in __getitem__
    list_ = super().__getitem__(key)
KeyError: ''

During handling of the above exception, another exception occurred:

Traceback (most recent call last):
  File "/usr/local/lib/python3.8/dist-packages/django/core/handlers/exception.py", line 47, in inner
    response = get_response(request)
  File "/usr/local/lib/python3.8/dist-packages/django/core/handlers/base.py", line 181, in _get_response
    response = wrapped_callback(request, *callback_args, **callback_kwargs)
  File "/usr/local/lib/python3.8/dist-packages/django/contrib/auth/decorators.py", line 21, in _wrapped_view
    return view_func(request, *args, **kwargs)
  File "/Anty/main/Anty/views/listing.py", line 40, in listing_detail
    temp_product = request.GET[""]
  File "/usr/local/lib/python3.8/dist-packages/django/utils/datastructures.py", line 78, in __getitem__
    raise MultiValueDictKeyError(key)
django.utils.datastructures.MultiValueDictKeyError: ''
ERROR:django.request:Internal Server Error: /listing_detail/
Traceback (most recent call last):
  File "/usr/local/lib/python3.8/dist-packages/django/utils/datastructures.py", line 76, in __getitem__
    list_ = super().__getitem__(key)
KeyError: ''

During handling of the above exception, another exception occurred:

Traceback (most recent call last):
  File "/usr/local/lib/python3.8/dist-packages/django/core/handlers/exception.py", line 47, in inner
    response = get_response(request)
  File "/usr/local/lib/python3.8/dist-packages/django/core/handlers/base.py", line 181, in _get_response
    response = wrapped_callback(request, *callback_args, **callback_kwargs)
  File "/usr/local/lib/python3.8/dist-packages/django/contrib/auth/decorators.py", line 21, in _wrapped_view
    return view_func(request, *args, **kwargs)
  File "/Anty/main/Anty/views/listing.py", line 40, in listing_detail
    temp_product = request.GET[""]
  File "/usr/local/lib/python3.8/dist-packages/django/utils/datastructures.py", line 78, in __getitem__
    raise MultiValueDictKeyError(key)
django.utils.datastructures.MultiValueDictKeyError: ''
INFO:django.utils.autoreload:/Anty/main/Anty/views/listing.py changed, reloading.
ERROR:django.request:Internal Server Error: /listing_detail/
Traceback (most recent call last):
  File "/usr/local/lib/python3.8/dist-packages/django/core/handlers/exception.py", line 47, in inner
    response = get_response(request)
  File "/usr/local/lib/python3.8/dist-packages/django/core/handlers/base.py", line 188, in _get_response
    self.check_response(response, callback)
  File "/usr/local/lib/python3.8/dist-packages/django/core/handlers/base.py", line 309, in check_response
    raise ValueError(
ValueError: The view Anty.views.listing.listing_detail didn't return an HttpResponse object. It returned None instead.
INFO:django.utils.autoreload:/Anty/main/Anty/views/listing.py changed, reloading.
ERROR:django.request:Internal Server Error: /listing_detail/
Traceback (most recent call last):
  File "/usr/local/lib/python3.8/dist-packages/django/core/handlers/exception.py", line 47, in inner
    response = get_response(request)
  File "/usr/local/lib/python3.8/dist-packages/django/core/handlers/base.py", line 181, in _get_response
    response = wrapped_callback(request, *callback_args, **callback_kwargs)
  File "/usr/local/lib/python3.8/dist-packages/django/contrib/auth/decorators.py", line 21, in _wrapped_view
    return view_func(request, *args, **kwargs)
  File "/Anty/main/Anty/views/listing.py", line 41, in listing_detail
    return render(request, template_name)
  File "/usr/local/lib/python3.8/dist-packages/django/shortcuts.py", line 19, in render
    content = loader.render_to_string(template_name, context, request, using=using)
  File "/usr/local/lib/python3.8/dist-packages/django/template/loader.py", line 61, in render_to_string
    template = get_template(template_name, using=using)
  File "/usr/local/lib/python3.8/dist-packages/django/template/loader.py", line 19, in get_template
    raise TemplateDoesNotExist(template_name, chain=chain)
django.template.exceptions.TemplateDoesNotExist: listing_detail.html
WARNING:django.request:Not Found: /js/slick.js
WARNING:django.request:Not Found: /js/index.js
WARNING:django.request:Not Found: /js/index.js
WARNING:django.request:Not Found: /js/slick.js
WARNING:django.request:Not Found: /js/slick.js
WARNING:django.request:Not Found: /js/index.js
WARNING:django.request:Not Found: /js/slick.js
WARNING:django.request:Not Found: /js/index.js
WARNING:django.request:Not Found: /js/index.js
WARNING:django.request:Not Found: /js/slick.js
WARNING:django.request:Not Found: /favicon.ico
WARNING:django.request:Not Found: /js/index.js
WARNING:django.request:Not Found: /js/slick.js
WARNING:django.request:Not Found: /js/index.js
WARNING:django.request:Not Found: /js/index.js
WARNING:django.request:Not Found: /js/slick.js
WARNING:django.request:Not Found: /js/index.js
WARNING:django.request:Not Found: /js/slick.js
WARNING:django.request:Not Found: /js/index.js
WARNING:django.request:Not Found: /js/index.js
WARNING:django.request:Not Found: /js/slick.js
WARNING:django.request:Not Found: /js/index.js
WARNING:django.request:Not Found: /js/slick.js
WARNING:django.request:Not Found: /js/index.js
WARNING:django.request:Not Found: /js/slick.js
WARNING:django.request:Not Found: /js/index.js
WARNING:django.request:Not Found: /js/index.js
WARNING:django.request:Not Found: /js/slick.js
WARNING:django.request:Not Found: /js/index.js
INFO:django.utils.autoreload:/Anty/main/Anty/views/listing.py changed, reloading.
INFO:django.utils.autoreload:/Anty/main/Anty/views/listing.py changed, reloading.
INFO:django.utils.autoreload:/Anty/main/Anty/views/listing.py changed, reloading.
WARNING:django.request:Not Found: /boaform/admin/formLogin
WARNING:django.request:Not Found: /js/slick.js
WARNING:django.request:Not Found: /js/index.js
ERROR:django.request:Internal Server Error: /listing_detail/
Traceback (most recent call last):
  File "/usr/local/lib/python3.8/dist-packages/django/core/handlers/exception.py", line 47, in inner
    response = get_response(request)
  File "/usr/local/lib/python3.8/dist-packages/django/core/handlers/base.py", line 181, in _get_response
    response = wrapped_callback(request, *callback_args, **callback_kwargs)
  File "/usr/local/lib/python3.8/dist-packages/django/contrib/auth/decorators.py", line 21, in _wrapped_view
    return view_func(request, *args, **kwargs)
  File "/Anty/main/Anty/views/listing.py", line 49, in listing_detail
    return render(request, template_name, params)
  File "/usr/local/lib/python3.8/dist-packages/django/shortcuts.py", line 19, in render
    content = loader.render_to_string(template_name, context, request, using=using)
  File "/usr/local/lib/python3.8/dist-packages/django/template/loader.py", line 61, in render_to_string
    template = get_template(template_name, using=using)
  File "/usr/local/lib/python3.8/dist-packages/django/template/loader.py", line 19, in get_template
    raise TemplateDoesNotExist(template_name, chain=chain)
django.template.exceptions.TemplateDoesNotExist: listing_detail.html
ERROR:django.request:Internal Server Error: /listing_detail/
Traceback (most recent call last):
  File "/usr/local/lib/python3.8/dist-packages/django/core/handlers/exception.py", line 47, in inner
    response = get_response(request)
  File "/usr/local/lib/python3.8/dist-packages/django/core/handlers/base.py", line 181, in _get_response
    response = wrapped_callback(request, *callback_args, **callback_kwargs)
  File "/usr/local/lib/python3.8/dist-packages/django/contrib/auth/decorators.py", line 21, in _wrapped_view
    return view_func(request, *args, **kwargs)
  File "/Anty/main/Anty/views/listing.py", line 49, in listing_detail
    return render(request, template_name, params)
  File "/usr/local/lib/python3.8/dist-packages/django/shortcuts.py", line 19, in render
    content = loader.render_to_string(template_name, context, request, using=using)
  File "/usr/local/lib/python3.8/dist-packages/django/template/loader.py", line 61, in render_to_string
    template = get_template(template_name, using=using)
  File "/usr/local/lib/python3.8/dist-packages/django/template/loader.py", line 19, in get_template
    raise TemplateDoesNotExist(template_name, chain=chain)
django.template.exceptions.TemplateDoesNotExist: listing_detail.html
INFO:django.utils.autoreload:/Anty/main/Anty/views/listing.py changed, reloading.
ERROR:django.request:Internal Server Error: /listing_detail/
Traceback (most recent call last):
  File "/usr/local/lib/python3.8/dist-packages/django/core/handlers/exception.py", line 47, in inner
    response = get_response(request)
  File "/usr/local/lib/python3.8/dist-packages/django/core/handlers/base.py", line 181, in _get_response
    response = wrapped_callback(request, *callback_args, **callback_kwargs)
  File "/usr/local/lib/python3.8/dist-packages/django/contrib/auth/decorators.py", line 21, in _wrapped_view
    return view_func(request, *args, **kwargs)
  File "/Anty/main/Anty/views/listing.py", line 49, in listing_detail
    return render(request, template_name, params)
  File "/usr/local/lib/python3.8/dist-packages/django/shortcuts.py", line 19, in render
    content = loader.render_to_string(template_name, context, request, using=using)
  File "/usr/local/lib/python3.8/dist-packages/django/template/loader.py", line 61, in render_to_string
    template = get_template(template_name, using=using)
  File "/usr/local/lib/python3.8/dist-packages/django/template/loader.py", line 15, in get_template
    return engine.get_template(template_name)
  File "/usr/local/lib/python3.8/dist-packages/django/template/backends/django.py", line 34, in get_template
    return Template(self.engine.get_template(template_name), self)
  File "/usr/local/lib/python3.8/dist-packages/django/template/engine.py", line 143, in get_template
    template, origin = self.find_template(template_name)
  File "/usr/local/lib/python3.8/dist-packages/django/template/engine.py", line 125, in find_template
    template = loader.get_template(name, skip=skip)
  File "/usr/local/lib/python3.8/dist-packages/django/template/loaders/base.py", line 29, in get_template
    return Template(
  File "/usr/local/lib/python3.8/dist-packages/django/template/base.py", line 155, in __init__
    self.nodelist = self.compile_nodelist()
  File "/usr/local/lib/python3.8/dist-packages/django/template/base.py", line 193, in compile_nodelist
    return parser.parse()
  File "/usr/local/lib/python3.8/dist-packages/django/template/base.py", line 449, in parse
    raise self.error(token, e)
  File "/usr/local/lib/python3.8/dist-packages/django/template/base.py", line 447, in parse
    filter_expression = self.compile_filter(token.contents)
  File "/usr/local/lib/python3.8/dist-packages/django/template/base.py", line 563, in compile_filter
    return FilterExpression(token, self)
  File "/usr/local/lib/python3.8/dist-packages/django/template/base.py", line 662, in __init__
    raise TemplateSyntaxError("Could not parse the remainder: '%s' "
django.template.exceptions.TemplateSyntaxError: Could not parse the remainder: '/id' from 'temp_product.brand/id'
INFO:django.utils.autoreload:/Anty/main/Anty/models.py changed, reloading.
INFO:django.utils.autoreload:/Anty/main/Anty/models.py changed, reloading.
INFO:django.utils.autoreload:/Anty/main/Anty/models.py changed, reloading.
INFO:django.utils.autoreload:/Anty/main/Anty/views/listing.py changed, reloading.
WARNING:django.request:Not Found: /boaform/admin/formLogin
ERROR:django.request:Internal Server Error: /listing_detail/
Traceback (most recent call last):
  File "/usr/local/lib/python3.8/dist-packages/django/core/handlers/exception.py", line 47, in inner
    response = get_response(request)
  File "/usr/local/lib/python3.8/dist-packages/django/core/handlers/base.py", line 181, in _get_response
    response = wrapped_callback(request, *callback_args, **callback_kwargs)
  File "/usr/local/lib/python3.8/dist-packages/django/contrib/auth/decorators.py", line 21, in _wrapped_view
    return view_func(request, *args, **kwargs)
  File "/Anty/main/Anty/views/listing.py", line 45, in listing_detail
    sche_shipping_date = Sche_shipping_date.objects.all()
NameError: name 'Sche_shipping_date' is not defined
WARNING:django.request:Not Found: /favicon.ico
WARNING:django.request:Not Found: /robots.txt
WARNING:django.request:Not Found: /.well-known/security.txt
INFO:django.utils.autoreload:/Anty/main/Anty/views/listing.py changed, reloading.
ERROR:django.request:Internal Server Error: /listing_detail/
Traceback (most recent call last):
  File "/usr/local/lib/python3.8/dist-packages/django/template/base.py", line 470, in parse
    compile_func = self.tags[command]
KeyError: 'endif'

During handling of the above exception, another exception occurred:

Traceback (most recent call last):
  File "/usr/local/lib/python3.8/dist-packages/django/core/handlers/exception.py", line 47, in inner
    response = get_response(request)
  File "/usr/local/lib/python3.8/dist-packages/django/core/handlers/base.py", line 181, in _get_response
    response = wrapped_callback(request, *callback_args, **callback_kwargs)
  File "/usr/local/lib/python3.8/dist-packages/django/contrib/auth/decorators.py", line 21, in _wrapped_view
    return view_func(request, *args, **kwargs)
  File "/Anty/main/Anty/views/listing.py", line 55, in listing_detail
    return render(request, template_name, params)
  File "/usr/local/lib/python3.8/dist-packages/django/shortcuts.py", line 19, in render
    content = loader.render_to_string(template_name, context, request, using=using)
  File "/usr/local/lib/python3.8/dist-packages/django/template/loader.py", line 61, in render_to_string
    template = get_template(template_name, using=using)
  File "/usr/local/lib/python3.8/dist-packages/django/template/loader.py", line 15, in get_template
    return engine.get_template(template_name)
  File "/usr/local/lib/python3.8/dist-packages/django/template/backends/django.py", line 34, in get_template
    return Template(self.engine.get_template(template_name), self)
  File "/usr/local/lib/python3.8/dist-packages/django/template/engine.py", line 143, in get_template
    template, origin = self.find_template(template_name)
  File "/usr/local/lib/python3.8/dist-packages/django/template/engine.py", line 125, in find_template
    template = loader.get_template(name, skip=skip)
  File "/usr/local/lib/python3.8/dist-packages/django/template/loaders/base.py", line 29, in get_template
    return Template(
  File "/usr/local/lib/python3.8/dist-packages/django/template/base.py", line 155, in __init__
    self.nodelist = self.compile_nodelist()
  File "/usr/local/lib/python3.8/dist-packages/django/template/base.py", line 193, in compile_nodelist
    return parser.parse()
  File "/usr/local/lib/python3.8/dist-packages/django/template/base.py", line 478, in parse
    raise self.error(token, e)
  File "/usr/local/lib/python3.8/dist-packages/django/template/base.py", line 476, in parse
    compiled_result = compile_func(self, token)
  File "/usr/local/lib/python3.8/dist-packages/django/template/defaulttags.py", line 814, in do_for
    nodelist_loop = parser.parse(('empty', 'endfor',))
  File "/usr/local/lib/python3.8/dist-packages/django/template/base.py", line 472, in parse
    self.invalid_block_tag(token, command, parse_until)
  File "/usr/local/lib/python3.8/dist-packages/django/template/base.py", line 522, in invalid_block_tag
    raise self.error(
django.template.exceptions.TemplateSyntaxError: Invalid block tag on line 113: 'endif', expected 'empty' or 'endfor'. Did you forget to register or load this tag?
WARNING:django.request:Not Found: /listing_detail/item-Verification.html
INFO:django.utils.autoreload:/Anty/main/Anty/models.py changed, reloading.
WARNING:django.request:Not Found: /home.html
WARNING:django.request:Not Found: /home.html
WARNING:django.request:Not Found: /home
WARNING:django.request:Not Found: /mypage/update.html
WARNING:django.request:Not Found: /item/item.html
WARNING:django.request:Not Found: /js/index.js
WARNING:django.request:Not Found: /js/slick.js
WARNING:django.request:Not Found: /js/slick.js
WARNING:django.request:Not Found: /js/index.js
WARNING:django.request:Not Found: /home.html
WARNING:django.request:Not Found: /js/slick.js
WARNING:django.request:Not Found: /js/index.js
WARNING:django.request:Not Found: /favicon.ico
WARNING:django.request:Not Found: /listing_detail/item-Verification.html
WARNING:django.request:Not Found: /listing_detail/item-Verification.html
WARNING:django.request:Not Found: /home.html
WARNING:django.request:Not Found: /mypage/update.html
WARNING:django.request:Not Found: /js/index.js
WARNING:django.request:Not Found: /js/slick.js
WARNING:django.request:Not Found: /js/slick.js
WARNING:django.request:Not Found: /js/index.js
WARNING:django.request:Not Found: /js/slick.js
WARNING:django.request:Not Found: /js/index.js
WARNING:django.request:Not Found: /js/slick.js
WARNING:django.request:Not Found: /js/index.js
WARNING:django.request:Not Found: /js/index.js
WARNING:django.request:Not Found: /js/slick.js
WARNING:django.request:Not Found: /js/index.js
WARNING:django.request:Not Found: /js/slick.js
WARNING:django.request:Not Found: /js/index.js
WARNING:django.request:Not Found: /js/slick.js
WARNING:django.request:Not Found: /js/index.js
WARNING:django.request:Not Found: /js/slick.js
INFO:django.utils.autoreload:/Anty/main/Anty/views/listing.py changed, reloading.
WARNING:django.request:Not Found: /js/slick.js
WARNING:django.request:Not Found: /js/index.js
INFO:django.utils.autoreload:/Anty/main/Anty/views/listing.py changed, reloading.
WARNING:django.request:Not Found: /js/slick.js
WARNING:django.request:Not Found: /js/index.js
WARNING:django.request:Not Found: /js/index.js
WARNING:django.request:Not Found: /js/slick.js
WARNING:django.request:Not Found: /js/slick.js
WARNING:django.request:Not Found: /js/index.js
WARNING:django.request:Not Found: /js/index.js
WARNING:django.request:Not Found: /js/slick.js
WARNING:django.request:Not Found: /js/slick.js
WARNING:django.request:Not Found: /js/index.js
WARNING:django.request:Not Found: /js/slick.js
WARNING:django.request:Not Found: /js/index.js
WARNING:django.request:Not Found: /js/slick.js
WARNING:django.request:Not Found: /js/index.js
WARNING:django.request:Not Found: /js/slick.js
WARNING:django.request:Not Found: /js/index.js
WARNING:django.request:Not Found: /js/slick.js
WARNING:django.request:Not Found: /js/index.js
WARNING:django.request:Not Found: /js/slick.js
WARNING:django.request:Not Found: /js/index.js
WARNING:django.request:Not Found: /js/slick.js
WARNING:django.request:Not Found: /js/index.js
WARNING:django.request:Not Found: /js/slick.js
WARNING:django.request:Not Found: /js/index.js
WARNING:django.request:Not Found: /js/slick.js
WARNING:django.request:Not Found: /js/index.js
WARNING:django.request:Not Found: /js/slick.js
WARNING:django.request:Not Found: /js/index.js
WARNING:django.request:Not Found: /js/slick.js
WARNING:django.request:Not Found: /js/index.js
WARNING:django.request:Not Found: /js/slick.js
WARNING:django.request:Not Found: /js/index.js
WARNING:django.request:Not Found: /js/slick.js
WARNING:django.request:Not Found: /js/index.js
WARNING:django.request:Not Found: /js/slick.js
WARNING:django.request:Not Found: /js/index.js
WARNING:django.request:Not Found: /config/getuser
WARNING:django.request:Not Found: /mypage/update.html
WARNING:django.request:Not Found: /mypage/update.html
WARNING:django.request:Not Found: /item/item.html
WARNING:django.request:Not Found: /home.html
WARNING:django.request:Not Found: /webfig/
WARNING:django.request:Not Found: /js/slick.js
WARNING:django.request:Not Found: /js/index.js
WARNING:django.request:Not Found: /favicon.ico
WARNING:django.request:Not Found: /system_api.php
WARNING:django.request:Not Found: /c/version.js
WARNING:django.request:Not Found: /streaming/clients_live.php
WARNING:django.request:Not Found: /stalker_portal/c/version.js
WARNING:django.request:Not Found: /stream/live.php
WARNING:django.request:Not Found: /flu/403.html
WARNING:django.request:Not Found: /gemini-iptv/vod.json
WARNING:django.request:Not Found: /gemini-iptv/get_prc.php
WARNING:django.request:Not Found: /system_api.php
WARNING:django.request:Not Found: /c/version.js
WARNING:django.request:Not Found: /streaming/clients_live.php
WARNING:django.request:Not Found: /stalker_portal/c/version.js
WARNING:django.request:Not Found: /stream/live.php
WARNING:django.request:Not Found: /flu/403.html
INFO:django.utils.autoreload:/Anty/main/Anty/views/listing.py changed, reloading.
WARNING:django.request:Not Found: /favicon.ico
WARNING:django.request:Not Found: /js/index.js
WARNING:django.request:Not Found: /js/slick.js
WARNING:django.request:Not Found: /js/index.js
ERROR:django.request:Internal Server Error: /listing_detail/
Traceback (most recent call last):
  File "/usr/local/lib/python3.8/dist-packages/django/core/handlers/exception.py", line 47, in inner
    response = get_response(request)
  File "/usr/local/lib/python3.8/dist-packages/django/core/handlers/base.py", line 181, in _get_response
    response = wrapped_callback(request, *callback_args, **callback_kwargs)
  File "/usr/local/lib/python3.8/dist-packages/django/contrib/auth/decorators.py", line 21, in _wrapped_view
    return view_func(request, *args, **kwargs)
  File "/Anty/main/Anty/views/listing.py", line 52, in listing_detail
    image = request.FILES["image_"+count]
TypeError: can only concatenate str (not "int") to str
INFO:django.utils.autoreload:/Anty/main/Anty/views/listing.py changed, reloading.
INFO:django.utils.autoreload:/Anty/main/Anty/views/listing.py changed, reloading.
ERROR:django.request:Internal Server Error: /listing_detail/
Traceback (most recent call last):
  File "/usr/local/lib/python3.8/dist-packages/django/utils/datastructures.py", line 76, in __getitem__
    list_ = super().__getitem__(key)
KeyError: 'image_1'

During handling of the above exception, another exception occurred:

Traceback (most recent call last):
  File "/usr/local/lib/python3.8/dist-packages/django/core/handlers/exception.py", line 47, in inner
    response = get_response(request)
  File "/usr/local/lib/python3.8/dist-packages/django/core/handlers/base.py", line 181, in _get_response
    response = wrapped_callback(request, *callback_args, **callback_kwargs)
  File "/usr/local/lib/python3.8/dist-packages/django/contrib/auth/decorators.py", line 21, in _wrapped_view
    return view_func(request, *args, **kwargs)
  File "/Anty/main/Anty/views/listing.py", line 64, in listing_detail
    image = request.FILES["image_"+str(count)]
  File "/usr/local/lib/python3.8/dist-packages/django/utils/datastructures.py", line 78, in __getitem__
    raise MultiValueDictKeyError(key)
django.utils.datastructures.MultiValueDictKeyError: 'image_1'
WARNING:django.request:Not Found: /favicon.ico
WARNING:django.request:Not Found: /js/slick.js
WARNING:django.request:Not Found: /js/index.js
WARNING:django.request:Not Found: /sele
WARNING:django.request:Not Found: /js/index.js
WARNING:django.request:Not Found: /js/slick.js
WARNING:django.request:Not Found: /js/index.js
WARNING:django.request:Not Found: /js/slick.js
WARNING:django.request:Not Found: /js/slick.js
WARNING:django.request:Not Found: /js/index.js
INFO:django.utils.autoreload:/Anty/main/Anty/views/listing.py changed, reloading.
ERROR:django.request:Internal Server Error: /listing_detail/
Traceback (most recent call last):
  File "/usr/local/lib/python3.8/dist-packages/django/core/handlers/exception.py", line 47, in inner
    response = get_response(request)
  File "/usr/local/lib/python3.8/dist-packages/django/core/handlers/base.py", line 181, in _get_response
    response = wrapped_callback(request, *callback_args, **callback_kwargs)
  File "/usr/local/lib/python3.8/dist-packages/django/contrib/auth/decorators.py", line 21, in _wrapped_view
    return view_func(request, *args, **kwargs)
  File "/Anty/main/Anty/views/listing.py", line 58, in listing_detail
    return render(request, "listing/item_input.html", params)
  File "/usr/local/lib/python3.8/dist-packages/django/shortcuts.py", line 19, in render
    content = loader.render_to_string(template_name, context, request, using=using)
  File "/usr/local/lib/python3.8/dist-packages/django/template/loader.py", line 61, in render_to_string
    template = get_template(template_name, using=using)
  File "/usr/local/lib/python3.8/dist-packages/django/template/loader.py", line 19, in get_template
    raise TemplateDoesNotExist(template_name, chain=chain)
django.template.exceptions.TemplateDoesNotExist: listing/item_input.html
INFO:django.utils.autoreload:/Anty/main/Anty/views/listing.py changed, reloading.
WARNING:django.request:Not Found: /images/iconmonstr-clothing-2-240 (3) 1.png
WARNING:django.request:Not Found: /images/Group 108.png
WARNING:django.request:Not Found: /images/iconmonstr-help-2-240 1.png
WARNING:django.request:Not Found: /images/3ED5D2F8-2461-440D-8606-6C3727318366.png
WARNING:django.request:Not Found: /images/C8677318-C64B-43E5-BD90-90BD6EBC3B80.png
ERROR:django.request:Internal Server Error: /listing_detail/
Traceback (most recent call last):
  File "/usr/local/lib/python3.8/dist-packages/django/core/handlers/exception.py", line 47, in inner
    response = get_response(request)
  File "/usr/local/lib/python3.8/dist-packages/django/core/handlers/base.py", line 181, in _get_response
    response = wrapped_callback(request, *callback_args, **callback_kwargs)
  File "/usr/local/lib/python3.8/dist-packages/django/contrib/auth/decorators.py", line 21, in _wrapped_view
    return view_func(request, *args, **kwargs)
  File "/Anty/main/Anty/views/listing.py", line 58, in listing_detail
    return render(request, "listing/item-input.html", params)
  File "/usr/local/lib/python3.8/dist-packages/django/shortcuts.py", line 19, in render
    content = loader.render_to_string(template_name, context, request, using=using)
  File "/usr/local/lib/python3.8/dist-packages/django/template/loader.py", line 61, in render_to_string
    template = get_template(template_name, using=using)
  File "/usr/local/lib/python3.8/dist-packages/django/template/loader.py", line 19, in get_template
    raise TemplateDoesNotExist(template_name, chain=chain)
django.template.exceptions.TemplateDoesNotExist: listing/item-input.html
ERROR:django.request:Internal Server Error: /listing_detail/
Traceback (most recent call last):
  File "/usr/local/lib/python3.8/dist-packages/django/core/handlers/exception.py", line 47, in inner
    response = get_response(request)
  File "/usr/local/lib/python3.8/dist-packages/django/core/handlers/base.py", line 181, in _get_response
    response = wrapped_callback(request, *callback_args, **callback_kwargs)
  File "/usr/local/lib/python3.8/dist-packages/django/contrib/auth/decorators.py", line 21, in _wrapped_view
    return view_func(request, *args, **kwargs)
  File "/Anty/main/Anty/views/listing.py", line 58, in listing_detail
    return render(request, "listing/item-input.html", params)
  File "/usr/local/lib/python3.8/dist-packages/django/shortcuts.py", line 19, in render
    content = loader.render_to_string(template_name, context, request, using=using)
  File "/usr/local/lib/python3.8/dist-packages/django/template/loader.py", line 61, in render_to_string
    template = get_template(template_name, using=using)
  File "/usr/local/lib/python3.8/dist-packages/django/template/loader.py", line 19, in get_template
    raise TemplateDoesNotExist(template_name, chain=chain)
django.template.exceptions.TemplateDoesNotExist: listing/item-input.html
ERROR:django.request:Internal Server Error: /listing_detail/
Traceback (most recent call last):
  File "/usr/local/lib/python3.8/dist-packages/django/core/handlers/exception.py", line 47, in inner
    response = get_response(request)
  File "/usr/local/lib/python3.8/dist-packages/django/core/handlers/base.py", line 181, in _get_response
    response = wrapped_callback(request, *callback_args, **callback_kwargs)
  File "/usr/local/lib/python3.8/dist-packages/django/contrib/auth/decorators.py", line 21, in _wrapped_view
    return view_func(request, *args, **kwargs)
  File "/Anty/main/Anty/views/listing.py", line 58, in listing_detail
    return render(request, "listing/item-input.html", params)
  File "/usr/local/lib/python3.8/dist-packages/django/shortcuts.py", line 19, in render
    content = loader.render_to_string(template_name, context, request, using=using)
  File "/usr/local/lib/python3.8/dist-packages/django/template/loader.py", line 61, in render_to_string
    template = get_template(template_name, using=using)
  File "/usr/local/lib/python3.8/dist-packages/django/template/loader.py", line 19, in get_template
    raise TemplateDoesNotExist(template_name, chain=chain)
django.template.exceptions.TemplateDoesNotExist: listing/item-input.html
ERROR:django.request:Internal Server Error: /listing_detail/
Traceback (most recent call last):
  File "/usr/local/lib/python3.8/dist-packages/django/core/handlers/exception.py", line 47, in inner
    response = get_response(request)
  File "/usr/local/lib/python3.8/dist-packages/django/core/handlers/base.py", line 181, in _get_response
    response = wrapped_callback(request, *callback_args, **callback_kwargs)
  File "/usr/local/lib/python3.8/dist-packages/django/contrib/auth/decorators.py", line 21, in _wrapped_view
    return view_func(request, *args, **kwargs)
  File "/Anty/main/Anty/views/listing.py", line 58, in listing_detail
    return render(request, "listing/item-input.html", params)
  File "/usr/local/lib/python3.8/dist-packages/django/shortcuts.py", line 19, in render
    content = loader.render_to_string(template_name, context, request, using=using)
  File "/usr/local/lib/python3.8/dist-packages/django/template/loader.py", line 61, in render_to_string
    template = get_template(template_name, using=using)
  File "/usr/local/lib/python3.8/dist-packages/django/template/loader.py", line 19, in get_template
    raise TemplateDoesNotExist(template_name, chain=chain)
django.template.exceptions.TemplateDoesNotExist: listing/item-input.html
ERROR:django.request:Internal Server Error: /listing_detail/
Traceback (most recent call last):
  File "/usr/local/lib/python3.8/dist-packages/django/core/handlers/exception.py", line 47, in inner
    response = get_response(request)
  File "/usr/local/lib/python3.8/dist-packages/django/core/handlers/base.py", line 181, in _get_response
    response = wrapped_callback(request, *callback_args, **callback_kwargs)
  File "/usr/local/lib/python3.8/dist-packages/django/contrib/auth/decorators.py", line 21, in _wrapped_view
    return view_func(request, *args, **kwargs)
  File "/Anty/main/Anty/views/listing.py", line 58, in listing_detail
    return render(request, "listing/item-input.html", params)
  File "/usr/local/lib/python3.8/dist-packages/django/shortcuts.py", line 19, in render
    content = loader.render_to_string(template_name, context, request, using=using)
  File "/usr/local/lib/python3.8/dist-packages/django/template/loader.py", line 61, in render_to_string
    template = get_template(template_name, using=using)
  File "/usr/local/lib/python3.8/dist-packages/django/template/loader.py", line 19, in get_template
    raise TemplateDoesNotExist(template_name, chain=chain)
django.template.exceptions.TemplateDoesNotExist: listing/item-input.html
ERROR:django.request:Internal Server Error: /listing_detail/
Traceback (most recent call last):
  File "/usr/local/lib/python3.8/dist-packages/django/core/handlers/exception.py", line 47, in inner
    response = get_response(request)
  File "/usr/local/lib/python3.8/dist-packages/django/core/handlers/base.py", line 181, in _get_response
    response = wrapped_callback(request, *callback_args, **callback_kwargs)
  File "/usr/local/lib/python3.8/dist-packages/django/contrib/auth/decorators.py", line 21, in _wrapped_view
    return view_func(request, *args, **kwargs)
  File "/Anty/main/Anty/views/listing.py", line 58, in listing_detail
    return render(request, "listing/item-input.html", params)
  File "/usr/local/lib/python3.8/dist-packages/django/shortcuts.py", line 19, in render
    content = loader.render_to_string(template_name, context, request, using=using)
  File "/usr/local/lib/python3.8/dist-packages/django/template/loader.py", line 61, in render_to_string
    template = get_template(template_name, using=using)
  File "/usr/local/lib/python3.8/dist-packages/django/template/loader.py", line 19, in get_template
    raise TemplateDoesNotExist(template_name, chain=chain)
django.template.exceptions.TemplateDoesNotExist: listing/item-input.html
ERROR:django.request:Internal Server Error: /listing_detail/
Traceback (most recent call last):
  File "/usr/local/lib/python3.8/dist-packages/django/core/handlers/exception.py", line 47, in inner
    response = get_response(request)
  File "/usr/local/lib/python3.8/dist-packages/django/core/handlers/base.py", line 181, in _get_response
    response = wrapped_callback(request, *callback_args, **callback_kwargs)
  File "/usr/local/lib/python3.8/dist-packages/django/contrib/auth/decorators.py", line 21, in _wrapped_view
    return view_func(request, *args, **kwargs)
  File "/Anty/main/Anty/views/listing.py", line 58, in listing_detail
    return render(request, "listing/item-input.html", params)
  File "/usr/local/lib/python3.8/dist-packages/django/shortcuts.py", line 19, in render
    content = loader.render_to_string(template_name, context, request, using=using)
  File "/usr/local/lib/python3.8/dist-packages/django/template/loader.py", line 61, in render_to_string
    template = get_template(template_name, using=using)
  File "/usr/local/lib/python3.8/dist-packages/django/template/loader.py", line 19, in get_template
    raise TemplateDoesNotExist(template_name, chain=chain)
django.template.exceptions.TemplateDoesNotExist: listing/item-input.html
INFO:django.utils.autoreload:/Anty/main/Anty/views/listing.py changed, reloading.
WARNING:django.request:Not Found: /images/C8677318-C64B-43E5-BD90-90BD6EBC3B80.png
WARNING:django.request:Not Found: /images/iconmonstr-clothing-2-240 (3) 1.png
WARNING:django.request:Not Found: /images/3ED5D2F8-2461-440D-8606-6C3727318366.png
WARNING:django.request:Not Found: /images/iconmonstr-help-2-240 1.png
WARNING:django.request:Not Found: /images/iconmonstr-clothing-2-240 (3) 1.png
WARNING:django.request:Not Found: /images/C8677318-C64B-43E5-BD90-90BD6EBC3B80.png
WARNING:django.request:Not Found: /images/3ED5D2F8-2461-440D-8606-6C3727318366.png
WARNING:django.request:Not Found: /images/iconmonstr-help-2-240 1.png
WARNING:django.request:Not Found: /images/iconmonstr-clothing-2-240 (3) 1.png
WARNING:django.request:Not Found: /images/C8677318-C64B-43E5-BD90-90BD6EBC3B80.png
WARNING:django.request:Not Found: /images/3ED5D2F8-2461-440D-8606-6C3727318366.png
WARNING:django.request:Not Found: /images/iconmonstr-help-2-240 1.png
WARNING:django.request:Not Found: /images/iconmonstr-clothing-2-240 (3) 1.png
WARNING:django.request:Not Found: /images/C8677318-C64B-43E5-BD90-90BD6EBC3B80.png
WARNING:django.request:Not Found: /images/iconmonstr-help-2-240 1.png
WARNING:django.request:Not Found: /images/3ED5D2F8-2461-440D-8606-6C3727318366.png
WARNING:django.request:Not Found: /images/C8677318-C64B-43E5-BD90-90BD6EBC3B80.png
WARNING:django.request:Not Found: /images/3ED5D2F8-2461-440D-8606-6C3727318366.png
WARNING:django.request:Not Found: /images/iconmonstr-help-2-240 1.png
WARNING:django.request:Not Found: /images/iconmonstr-help-2-240 1.png
WARNING:django.request:Not Found: /images/3ED5D2F8-2461-440D-8606-6C3727318366.png
WARNING:django.request:Not Found: /images/iconmonstr-help-2-240 1.png
WARNING:django.request:Not Found: /images/3ED5D2F8-2461-440D-8606-6C3727318366.png
WARNING:django.request:Not Found: /images/iconmonstr-help-2-240 1.png
WARNING:django.request:Not Found: /images/iconmonstr-help-2-240 1.png
ERROR:django.request:Internal Server Error: /listing_detail/
Traceback (most recent call last):
  File "/usr/local/lib/python3.8/dist-packages/django/utils/datastructures.py", line 76, in __getitem__
    list_ = super().__getitem__(key)
KeyError: 'image_1'

During handling of the above exception, another exception occurred:

Traceback (most recent call last):
  File "/usr/local/lib/python3.8/dist-packages/django/core/handlers/exception.py", line 47, in inner
    response = get_response(request)
  File "/usr/local/lib/python3.8/dist-packages/django/core/handlers/base.py", line 181, in _get_response
    response = wrapped_callback(request, *callback_args, **callback_kwargs)
  File "/usr/local/lib/python3.8/dist-packages/django/contrib/auth/decorators.py", line 21, in _wrapped_view
    return view_func(request, *args, **kwargs)
  File "/Anty/main/Anty/views/listing.py", line 64, in listing_detail
    image = request.FILES["image_"+str(count)]
  File "/usr/local/lib/python3.8/dist-packages/django/utils/datastructures.py", line 78, in __getitem__
    raise MultiValueDictKeyError(key)
django.utils.datastructures.MultiValueDictKeyError: 'image_1'
ERROR:django.request:Internal Server Error: /listing_detail/
Traceback (most recent call last):
  File "/usr/local/lib/python3.8/dist-packages/django/utils/datastructures.py", line 76, in __getitem__
    list_ = super().__getitem__(key)
KeyError: 'image_1'

During handling of the above exception, another exception occurred:

Traceback (most recent call last):
  File "/usr/local/lib/python3.8/dist-packages/django/core/handlers/exception.py", line 47, in inner
    response = get_response(request)
  File "/usr/local/lib/python3.8/dist-packages/django/core/handlers/base.py", line 181, in _get_response
    response = wrapped_callback(request, *callback_args, **callback_kwargs)
  File "/usr/local/lib/python3.8/dist-packages/django/contrib/auth/decorators.py", line 21, in _wrapped_view
    return view_func(request, *args, **kwargs)
  File "/Anty/main/Anty/views/listing.py", line 64, in listing_detail
    image = request.FILES["image_"+str(count)]
  File "/usr/local/lib/python3.8/dist-packages/django/utils/datastructures.py", line 78, in __getitem__
    raise MultiValueDictKeyError(key)
django.utils.datastructures.MultiValueDictKeyError: 'image_1'
INFO:django.utils.autoreload:/Anty/main/Anty/views/listing.py changed, reloading.
ERROR:django.request:Internal Server Error: /listing_detail/
Traceback (most recent call last):
  File "/usr/local/lib/python3.8/dist-packages/django/utils/datastructures.py", line 76, in __getitem__
    list_ = super().__getitem__(key)
KeyError: 'image_1'

During handling of the above exception, another exception occurred:

Traceback (most recent call last):
  File "/usr/local/lib/python3.8/dist-packages/django/core/handlers/exception.py", line 47, in inner
    response = get_response(request)
  File "/usr/local/lib/python3.8/dist-packages/django/core/handlers/base.py", line 181, in _get_response
    response = wrapped_callback(request, *callback_args, **callback_kwargs)
  File "/usr/local/lib/python3.8/dist-packages/django/contrib/auth/decorators.py", line 21, in _wrapped_view
    return view_func(request, *args, **kwargs)
  File "/Anty/main/Anty/views/listing.py", line 64, in listing_detail
    image = request.FILES[str("image_"+str(count))]
  File "/usr/local/lib/python3.8/dist-packages/django/utils/datastructures.py", line 78, in __getitem__
    raise MultiValueDictKeyError(key)
django.utils.datastructures.MultiValueDictKeyError: 'image_1'
ERROR:django.request:Internal Server Error: /listing_detail/
Traceback (most recent call last):
  File "/usr/local/lib/python3.8/dist-packages/django/utils/datastructures.py", line 76, in __getitem__
    list_ = super().__getitem__(key)
KeyError: 'image_1'

During handling of the above exception, another exception occurred:

Traceback (most recent call last):
  File "/usr/local/lib/python3.8/dist-packages/django/core/handlers/exception.py", line 47, in inner
    response = get_response(request)
  File "/usr/local/lib/python3.8/dist-packages/django/core/handlers/base.py", line 181, in _get_response
    response = wrapped_callback(request, *callback_args, **callback_kwargs)
  File "/usr/local/lib/python3.8/dist-packages/django/contrib/auth/decorators.py", line 21, in _wrapped_view
    return view_func(request, *args, **kwargs)
  File "/Anty/main/Anty/views/listing.py", line 64, in listing_detail
    image = request.FILES[str("image_"+str(count))]
  File "/usr/local/lib/python3.8/dist-packages/django/utils/datastructures.py", line 78, in __getitem__
    raise MultiValueDictKeyError(key)
django.utils.datastructures.MultiValueDictKeyError: 'image_1'
ERROR:django.request:Internal Server Error: /listing_detail/
Traceback (most recent call last):
  File "/usr/local/lib/python3.8/dist-packages/django/utils/datastructures.py", line 76, in __getitem__
    list_ = super().__getitem__(key)
KeyError: 'image_1'

During handling of the above exception, another exception occurred:

Traceback (most recent call last):
  File "/usr/local/lib/python3.8/dist-packages/django/core/handlers/exception.py", line 47, in inner
    response = get_response(request)
  File "/usr/local/lib/python3.8/dist-packages/django/core/handlers/base.py", line 181, in _get_response
    response = wrapped_callback(request, *callback_args, **callback_kwargs)
  File "/usr/local/lib/python3.8/dist-packages/django/contrib/auth/decorators.py", line 21, in _wrapped_view
    return view_func(request, *args, **kwargs)
  File "/Anty/main/Anty/views/listing.py", line 64, in listing_detail
    image = request.FILES[str("image_"+str(count))]
  File "/usr/local/lib/python3.8/dist-packages/django/utils/datastructures.py", line 78, in __getitem__
    raise MultiValueDictKeyError(key)
django.utils.datastructures.MultiValueDictKeyError: 'image_1'
ERROR:django.request:Internal Server Error: /listing_detail/
Traceback (most recent call last):
  File "/usr/local/lib/python3.8/dist-packages/django/utils/datastructures.py", line 76, in __getitem__
    list_ = super().__getitem__(key)
KeyError: 'image_1'

During handling of the above exception, another exception occurred:

Traceback (most recent call last):
  File "/usr/local/lib/python3.8/dist-packages/django/core/handlers/exception.py", line 47, in inner
    response = get_response(request)
  File "/usr/local/lib/python3.8/dist-packages/django/core/handlers/base.py", line 181, in _get_response
    response = wrapped_callback(request, *callback_args, **callback_kwargs)
  File "/usr/local/lib/python3.8/dist-packages/django/contrib/auth/decorators.py", line 21, in _wrapped_view
    return view_func(request, *args, **kwargs)
  File "/Anty/main/Anty/views/listing.py", line 64, in listing_detail
    image = request.FILES[str("image_"+str(count))]
  File "/usr/local/lib/python3.8/dist-packages/django/utils/datastructures.py", line 78, in __getitem__
    raise MultiValueDictKeyError(key)
django.utils.datastructures.MultiValueDictKeyError: 'image_1'
WARNING:django.request:Not Found: /images/iconmonstr-help-2-240 1.png
ERROR:django.request:Internal Server Error: /listing_detail/
Traceback (most recent call last):
  File "/usr/local/lib/python3.8/dist-packages/django/utils/datastructures.py", line 76, in __getitem__
    list_ = super().__getitem__(key)
KeyError: 'image_1'

During handling of the above exception, another exception occurred:

Traceback (most recent call last):
  File "/usr/local/lib/python3.8/dist-packages/django/core/handlers/exception.py", line 47, in inner
    response = get_response(request)
  File "/usr/local/lib/python3.8/dist-packages/django/core/handlers/base.py", line 181, in _get_response
    response = wrapped_callback(request, *callback_args, **callback_kwargs)
  File "/usr/local/lib/python3.8/dist-packages/django/contrib/auth/decorators.py", line 21, in _wrapped_view
    return view_func(request, *args, **kwargs)
  File "/Anty/main/Anty/views/listing.py", line 64, in listing_detail
    image = request.FILES[str("image_"+str(count))]
  File "/usr/local/lib/python3.8/dist-packages/django/utils/datastructures.py", line 78, in __getitem__
    raise MultiValueDictKeyError(key)
django.utils.datastructures.MultiValueDictKeyError: 'image_1'
INFO:django.utils.autoreload:/Anty/main/Anty/views/listing.py changed, reloading.
ERROR:django.request:Internal Server Error: /listing_detail/
Traceback (most recent call last):
  File "/usr/local/lib/python3.8/dist-packages/django/utils/datastructures.py", line 76, in __getitem__
    list_ = super().__getitem__(key)
KeyError: 'image_1'

During handling of the above exception, another exception occurred:

Traceback (most recent call last):
  File "/usr/local/lib/python3.8/dist-packages/django/core/handlers/exception.py", line 47, in inner
    response = get_response(request)
  File "/usr/local/lib/python3.8/dist-packages/django/core/handlers/base.py", line 181, in _get_response
    response = wrapped_callback(request, *callback_args, **callback_kwargs)
  File "/usr/local/lib/python3.8/dist-packages/django/contrib/auth/decorators.py", line 21, in _wrapped_view
    return view_func(request, *args, **kwargs)
  File "/Anty/main/Anty/views/listing.py", line 64, in listing_detail
    image = request.FILES[str("image_"+str(count))]
  File "/usr/local/lib/python3.8/dist-packages/django/utils/datastructures.py", line 78, in __getitem__
    raise MultiValueDictKeyError(key)
django.utils.datastructures.MultiValueDictKeyError: 'image_1'
ERROR:django.request:Internal Server Error: /listing_detail/
Traceback (most recent call last):
  File "/usr/local/lib/python3.8/dist-packages/django/utils/datastructures.py", line 76, in __getitem__
    list_ = super().__getitem__(key)
KeyError: 'image_1'

During handling of the above exception, another exception occurred:

Traceback (most recent call last):
  File "/usr/local/lib/python3.8/dist-packages/django/core/handlers/exception.py", line 47, in inner
    response = get_response(request)
  File "/usr/local/lib/python3.8/dist-packages/django/core/handlers/base.py", line 181, in _get_response
    response = wrapped_callback(request, *callback_args, **callback_kwargs)
  File "/usr/local/lib/python3.8/dist-packages/django/contrib/auth/decorators.py", line 21, in _wrapped_view
    return view_func(request, *args, **kwargs)
  File "/Anty/main/Anty/views/listing.py", line 64, in listing_detail
    image = request.FILES[str("image_"+str(count))]
  File "/usr/local/lib/python3.8/dist-packages/django/utils/datastructures.py", line 78, in __getitem__
    raise MultiValueDictKeyError(key)
django.utils.datastructures.MultiValueDictKeyError: 'image_1'
ERROR:django.request:Internal Server Error: /listing_detail/
Traceback (most recent call last):
  File "/usr/local/lib/python3.8/dist-packages/django/utils/datastructures.py", line 76, in __getitem__
    list_ = super().__getitem__(key)
KeyError: 'image_1'

During handling of the above exception, another exception occurred:

Traceback (most recent call last):
  File "/usr/local/lib/python3.8/dist-packages/django/core/handlers/exception.py", line 47, in inner
    response = get_response(request)
  File "/usr/local/lib/python3.8/dist-packages/django/core/handlers/base.py", line 181, in _get_response
    response = wrapped_callback(request, *callback_args, **callback_kwargs)
  File "/usr/local/lib/python3.8/dist-packages/django/contrib/auth/decorators.py", line 21, in _wrapped_view
    return view_func(request, *args, **kwargs)
  File "/Anty/main/Anty/views/listing.py", line 64, in listing_detail
    image = request.FILES[str("image_"+str(count))]
  File "/usr/local/lib/python3.8/dist-packages/django/utils/datastructures.py", line 78, in __getitem__
    raise MultiValueDictKeyError(key)
django.utils.datastructures.MultiValueDictKeyError: 'image_1'
ERROR:django.request:Internal Server Error: /listing_detail/
Traceback (most recent call last):
  File "/usr/local/lib/python3.8/dist-packages/django/utils/datastructures.py", line 76, in __getitem__
    list_ = super().__getitem__(key)
KeyError: 'image_1'

During handling of the above exception, another exception occurred:

Traceback (most recent call last):
  File "/usr/local/lib/python3.8/dist-packages/django/core/handlers/exception.py", line 47, in inner
    response = get_response(request)
  File "/usr/local/lib/python3.8/dist-packages/django/core/handlers/base.py", line 181, in _get_response
    response = wrapped_callback(request, *callback_args, **callback_kwargs)
  File "/usr/local/lib/python3.8/dist-packages/django/contrib/auth/decorators.py", line 21, in _wrapped_view
    return view_func(request, *args, **kwargs)
  File "/Anty/main/Anty/views/listing.py", line 64, in listing_detail
    image = request.FILES[str("image_"+str(count))]
  File "/usr/local/lib/python3.8/dist-packages/django/utils/datastructures.py", line 78, in __getitem__
    raise MultiValueDictKeyError(key)
django.utils.datastructures.MultiValueDictKeyError: 'image_1'
INFO:django.utils.autoreload:/Anty/main/Anty/views/listing.py changed, reloading.
INFO:django.utils.autoreload:/Anty/main/Anty/views/listing.py changed, reloading.
ERROR:django.request:Internal Server Error: /listing_detail/
Traceback (most recent call last):
  File "/usr/local/lib/python3.8/dist-packages/django/utils/datastructures.py", line 76, in __getitem__
    list_ = super().__getitem__(key)
KeyError: 'image_1'

During handling of the above exception, another exception occurred:

Traceback (most recent call last):
  File "/usr/local/lib/python3.8/dist-packages/django/core/handlers/exception.py", line 47, in inner
    response = get_response(request)
  File "/usr/local/lib/python3.8/dist-packages/django/core/handlers/base.py", line 181, in _get_response
    response = wrapped_callback(request, *callback_args, **callback_kwargs)
  File "/usr/local/lib/python3.8/dist-packages/django/contrib/auth/decorators.py", line 21, in _wrapped_view
    return view_func(request, *args, **kwargs)
  File "/Anty/main/Anty/views/listing.py", line 63, in listing_detail
    image = request.FILES["image_1"]
  File "/usr/local/lib/python3.8/dist-packages/django/utils/datastructures.py", line 78, in __getitem__
    raise MultiValueDictKeyError(key)
django.utils.datastructures.MultiValueDictKeyError: 'image_1'
INFO:django.utils.autoreload:/Anty/main/Anty/views/listing.py changed, reloading.
ERROR:django.request:Internal Server Error: /listing_detail/
Traceback (most recent call last):
  File "/usr/local/lib/python3.8/dist-packages/django/core/handlers/exception.py", line 47, in inner
    response = get_response(request)
  File "/usr/local/lib/python3.8/dist-packages/django/core/handlers/base.py", line 181, in _get_response
    response = wrapped_callback(request, *callback_args, **callback_kwargs)
  File "/usr/local/lib/python3.8/dist-packages/django/contrib/auth/decorators.py", line 21, in _wrapped_view
    return view_func(request, *args, **kwargs)
  File "/Anty/main/Anty/views/listing.py", line 72, in listing_detail
    return redirect("")
  File "/usr/local/lib/python3.8/dist-packages/django/shortcuts.py", line 41, in redirect
    return redirect_class(resolve_url(to, *args, **kwargs))
  File "/usr/local/lib/python3.8/dist-packages/django/shortcuts.py", line 130, in resolve_url
    return reverse(to, args=args, kwargs=kwargs)
  File "/usr/local/lib/python3.8/dist-packages/django/urls/base.py", line 86, in reverse
    return resolver._reverse_with_prefix(view, prefix, *args, **kwargs)
  File "/usr/local/lib/python3.8/dist-packages/django/urls/resolvers.py", line 694, in _reverse_with_prefix
    raise NoReverseMatch(msg)
django.urls.exceptions.NoReverseMatch: Reverse for '' not found. '' is not a valid view function or pattern name.
ERROR:django.request:Internal Server Error: /listing_detail/
Traceback (most recent call last):
  File "/usr/local/lib/python3.8/dist-packages/django/core/handlers/exception.py", line 47, in inner
    response = get_response(request)
  File "/usr/local/lib/python3.8/dist-packages/django/core/handlers/base.py", line 181, in _get_response
    response = wrapped_callback(request, *callback_args, **callback_kwargs)
  File "/usr/local/lib/python3.8/dist-packages/django/contrib/auth/decorators.py", line 21, in _wrapped_view
    return view_func(request, *args, **kwargs)
  File "/Anty/main/Anty/views/listing.py", line 72, in listing_detail
    return redirect("")
  File "/usr/local/lib/python3.8/dist-packages/django/shortcuts.py", line 41, in redirect
    return redirect_class(resolve_url(to, *args, **kwargs))
  File "/usr/local/lib/python3.8/dist-packages/django/shortcuts.py", line 130, in resolve_url
    return reverse(to, args=args, kwargs=kwargs)
  File "/usr/local/lib/python3.8/dist-packages/django/urls/base.py", line 86, in reverse
    return resolver._reverse_with_prefix(view, prefix, *args, **kwargs)
  File "/usr/local/lib/python3.8/dist-packages/django/urls/resolvers.py", line 694, in _reverse_with_prefix
    raise NoReverseMatch(msg)
django.urls.exceptions.NoReverseMatch: Reverse for '' not found. '' is not a valid view function or pattern name.
ERROR:django.request:Internal Server Error: /listing_detail/
Traceback (most recent call last):
  File "/usr/local/lib/python3.8/dist-packages/django/core/handlers/exception.py", line 47, in inner
    response = get_response(request)
  File "/usr/local/lib/python3.8/dist-packages/django/core/handlers/base.py", line 181, in _get_response
    response = wrapped_callback(request, *callback_args, **callback_kwargs)
  File "/usr/local/lib/python3.8/dist-packages/django/contrib/auth/decorators.py", line 21, in _wrapped_view
    return view_func(request, *args, **kwargs)
  File "/Anty/main/Anty/views/listing.py", line 72, in listing_detail
    return redirect("")
  File "/usr/local/lib/python3.8/dist-packages/django/shortcuts.py", line 41, in redirect
    return redirect_class(resolve_url(to, *args, **kwargs))
  File "/usr/local/lib/python3.8/dist-packages/django/shortcuts.py", line 130, in resolve_url
    return reverse(to, args=args, kwargs=kwargs)
  File "/usr/local/lib/python3.8/dist-packages/django/urls/base.py", line 86, in reverse
    return resolver._reverse_with_prefix(view, prefix, *args, **kwargs)
  File "/usr/local/lib/python3.8/dist-packages/django/urls/resolvers.py", line 694, in _reverse_with_prefix
    raise NoReverseMatch(msg)
django.urls.exceptions.NoReverseMatch: Reverse for '' not found. '' is not a valid view function or pattern name.
ERROR:django.request:Internal Server Error: /listing_detail/
Traceback (most recent call last):
  File "/usr/local/lib/python3.8/dist-packages/django/core/handlers/exception.py", line 47, in inner
    response = get_response(request)
  File "/usr/local/lib/python3.8/dist-packages/django/core/handlers/base.py", line 181, in _get_response
    response = wrapped_callback(request, *callback_args, **callback_kwargs)
  File "/usr/local/lib/python3.8/dist-packages/django/contrib/auth/decorators.py", line 21, in _wrapped_view
    return view_func(request, *args, **kwargs)
  File "/Anty/main/Anty/views/listing.py", line 72, in listing_detail
    return redirect("")
  File "/usr/local/lib/python3.8/dist-packages/django/shortcuts.py", line 41, in redirect
    return redirect_class(resolve_url(to, *args, **kwargs))
  File "/usr/local/lib/python3.8/dist-packages/django/shortcuts.py", line 130, in resolve_url
    return reverse(to, args=args, kwargs=kwargs)
  File "/usr/local/lib/python3.8/dist-packages/django/urls/base.py", line 86, in reverse
    return resolver._reverse_with_prefix(view, prefix, *args, **kwargs)
  File "/usr/local/lib/python3.8/dist-packages/django/urls/resolvers.py", line 694, in _reverse_with_prefix
    raise NoReverseMatch(msg)
django.urls.exceptions.NoReverseMatch: Reverse for '' not found. '' is not a valid view function or pattern name.
ERROR:django.request:Internal Server Error: /listing_detail/
Traceback (most recent call last):
  File "/usr/local/lib/python3.8/dist-packages/django/core/handlers/exception.py", line 47, in inner
    response = get_response(request)
  File "/usr/local/lib/python3.8/dist-packages/django/core/handlers/base.py", line 181, in _get_response
    response = wrapped_callback(request, *callback_args, **callback_kwargs)
  File "/usr/local/lib/python3.8/dist-packages/django/contrib/auth/decorators.py", line 21, in _wrapped_view
    return view_func(request, *args, **kwargs)
  File "/Anty/main/Anty/views/listing.py", line 72, in listing_detail
    return redirect("")
  File "/usr/local/lib/python3.8/dist-packages/django/shortcuts.py", line 41, in redirect
    return redirect_class(resolve_url(to, *args, **kwargs))
  File "/usr/local/lib/python3.8/dist-packages/django/shortcuts.py", line 130, in resolve_url
    return reverse(to, args=args, kwargs=kwargs)
  File "/usr/local/lib/python3.8/dist-packages/django/urls/base.py", line 86, in reverse
    return resolver._reverse_with_prefix(view, prefix, *args, **kwargs)
  File "/usr/local/lib/python3.8/dist-packages/django/urls/resolvers.py", line 694, in _reverse_with_prefix
    raise NoReverseMatch(msg)
django.urls.exceptions.NoReverseMatch: Reverse for '' not found. '' is not a valid view function or pattern name.
ERROR:django.request:Internal Server Error: /listing_detail/
Traceback (most recent call last):
  File "/usr/local/lib/python3.8/dist-packages/django/core/handlers/exception.py", line 47, in inner
    response = get_response(request)
  File "/usr/local/lib/python3.8/dist-packages/django/core/handlers/base.py", line 181, in _get_response
    response = wrapped_callback(request, *callback_args, **callback_kwargs)
  File "/usr/local/lib/python3.8/dist-packages/django/contrib/auth/decorators.py", line 21, in _wrapped_view
    return view_func(request, *args, **kwargs)
  File "/Anty/main/Anty/views/listing.py", line 72, in listing_detail
    return redirect("")
  File "/usr/local/lib/python3.8/dist-packages/django/shortcuts.py", line 41, in redirect
    return redirect_class(resolve_url(to, *args, **kwargs))
  File "/usr/local/lib/python3.8/dist-packages/django/shortcuts.py", line 130, in resolve_url
    return reverse(to, args=args, kwargs=kwargs)
  File "/usr/local/lib/python3.8/dist-packages/django/urls/base.py", line 86, in reverse
    return resolver._reverse_with_prefix(view, prefix, *args, **kwargs)
  File "/usr/local/lib/python3.8/dist-packages/django/urls/resolvers.py", line 694, in _reverse_with_prefix
    raise NoReverseMatch(msg)
django.urls.exceptions.NoReverseMatch: Reverse for '' not found. '' is not a valid view function or pattern name.
ERROR:django.request:Internal Server Error: /listing_detail/
Traceback (most recent call last):
  File "/usr/local/lib/python3.8/dist-packages/django/core/handlers/exception.py", line 47, in inner
    response = get_response(request)
  File "/usr/local/lib/python3.8/dist-packages/django/core/handlers/base.py", line 181, in _get_response
    response = wrapped_callback(request, *callback_args, **callback_kwargs)
  File "/usr/local/lib/python3.8/dist-packages/django/contrib/auth/decorators.py", line 21, in _wrapped_view
    return view_func(request, *args, **kwargs)
  File "/Anty/main/Anty/views/listing.py", line 72, in listing_detail
    return redirect("")
  File "/usr/local/lib/python3.8/dist-packages/django/shortcuts.py", line 41, in redirect
    return redirect_class(resolve_url(to, *args, **kwargs))
  File "/usr/local/lib/python3.8/dist-packages/django/shortcuts.py", line 130, in resolve_url
    return reverse(to, args=args, kwargs=kwargs)
  File "/usr/local/lib/python3.8/dist-packages/django/urls/base.py", line 86, in reverse
    return resolver._reverse_with_prefix(view, prefix, *args, **kwargs)
  File "/usr/local/lib/python3.8/dist-packages/django/urls/resolvers.py", line 694, in _reverse_with_prefix
    raise NoReverseMatch(msg)
django.urls.exceptions.NoReverseMatch: Reverse for '' not found. '' is not a valid view function or pattern name.
ERROR:django.request:Internal Server Error: /listing_detail/
Traceback (most recent call last):
  File "/usr/local/lib/python3.8/dist-packages/django/core/handlers/exception.py", line 47, in inner
    response = get_response(request)
  File "/usr/local/lib/python3.8/dist-packages/django/core/handlers/base.py", line 181, in _get_response
    response = wrapped_callback(request, *callback_args, **callback_kwargs)
  File "/usr/local/lib/python3.8/dist-packages/django/contrib/auth/decorators.py", line 21, in _wrapped_view
    return view_func(request, *args, **kwargs)
  File "/Anty/main/Anty/views/listing.py", line 72, in listing_detail
    return redirect("")
  File "/usr/local/lib/python3.8/dist-packages/django/shortcuts.py", line 41, in redirect
    return redirect_class(resolve_url(to, *args, **kwargs))
  File "/usr/local/lib/python3.8/dist-packages/django/shortcuts.py", line 130, in resolve_url
    return reverse(to, args=args, kwargs=kwargs)
  File "/usr/local/lib/python3.8/dist-packages/django/urls/base.py", line 86, in reverse
    return resolver._reverse_with_prefix(view, prefix, *args, **kwargs)
  File "/usr/local/lib/python3.8/dist-packages/django/urls/resolvers.py", line 694, in _reverse_with_prefix
    raise NoReverseMatch(msg)
django.urls.exceptions.NoReverseMatch: Reverse for '' not found. '' is not a valid view function or pattern name.
ERROR:django.request:Internal Server Error: /listing_detail/
Traceback (most recent call last):
  File "/usr/local/lib/python3.8/dist-packages/django/core/handlers/exception.py", line 47, in inner
    response = get_response(request)
  File "/usr/local/lib/python3.8/dist-packages/django/core/handlers/base.py", line 181, in _get_response
    response = wrapped_callback(request, *callback_args, **callback_kwargs)
  File "/usr/local/lib/python3.8/dist-packages/django/contrib/auth/decorators.py", line 21, in _wrapped_view
    return view_func(request, *args, **kwargs)
  File "/Anty/main/Anty/views/listing.py", line 72, in listing_detail
    return redirect("")
  File "/usr/local/lib/python3.8/dist-packages/django/shortcuts.py", line 41, in redirect
    return redirect_class(resolve_url(to, *args, **kwargs))
  File "/usr/local/lib/python3.8/dist-packages/django/shortcuts.py", line 130, in resolve_url
    return reverse(to, args=args, kwargs=kwargs)
  File "/usr/local/lib/python3.8/dist-packages/django/urls/base.py", line 86, in reverse
    return resolver._reverse_with_prefix(view, prefix, *args, **kwargs)
  File "/usr/local/lib/python3.8/dist-packages/django/urls/resolvers.py", line 694, in _reverse_with_prefix
    raise NoReverseMatch(msg)
django.urls.exceptions.NoReverseMatch: Reverse for '' not found. '' is not a valid view function or pattern name.
ERROR:django.request:Internal Server Error: /listing_detail/
Traceback (most recent call last):
  File "/usr/local/lib/python3.8/dist-packages/django/core/handlers/exception.py", line 47, in inner
    response = get_response(request)
  File "/usr/local/lib/python3.8/dist-packages/django/core/handlers/base.py", line 181, in _get_response
    response = wrapped_callback(request, *callback_args, **callback_kwargs)
  File "/usr/local/lib/python3.8/dist-packages/django/contrib/auth/decorators.py", line 21, in _wrapped_view
    return view_func(request, *args, **kwargs)
  File "/Anty/main/Anty/views/listing.py", line 72, in listing_detail
    return redirect("")
  File "/usr/local/lib/python3.8/dist-packages/django/shortcuts.py", line 41, in redirect
    return redirect_class(resolve_url(to, *args, **kwargs))
  File "/usr/local/lib/python3.8/dist-packages/django/shortcuts.py", line 130, in resolve_url
    return reverse(to, args=args, kwargs=kwargs)
  File "/usr/local/lib/python3.8/dist-packages/django/urls/base.py", line 86, in reverse
    return resolver._reverse_with_prefix(view, prefix, *args, **kwargs)
  File "/usr/local/lib/python3.8/dist-packages/django/urls/resolvers.py", line 694, in _reverse_with_prefix
    raise NoReverseMatch(msg)
django.urls.exceptions.NoReverseMatch: Reverse for '' not found. '' is not a valid view function or pattern name.
INFO:django.utils.autoreload:/Anty/main/Anty/views/listing.py changed, reloading.
ERROR:django.request:Internal Server Error: /listing_detail/
Traceback (most recent call last):
  File "/usr/local/lib/python3.8/dist-packages/django/core/handlers/exception.py", line 47, in inner
    response = get_response(request)
  File "/usr/local/lib/python3.8/dist-packages/django/core/handlers/base.py", line 181, in _get_response
    response = wrapped_callback(request, *callback_args, **callback_kwargs)
  File "/usr/local/lib/python3.8/dist-packages/django/contrib/auth/decorators.py", line 21, in _wrapped_view
    return view_func(request, *args, **kwargs)
  File "/Anty/main/Anty/views/listing.py", line 73, in listing_detail
    return redirect("")
  File "/usr/local/lib/python3.8/dist-packages/django/shortcuts.py", line 41, in redirect
    return redirect_class(resolve_url(to, *args, **kwargs))
  File "/usr/local/lib/python3.8/dist-packages/django/shortcuts.py", line 130, in resolve_url
    return reverse(to, args=args, kwargs=kwargs)
  File "/usr/local/lib/python3.8/dist-packages/django/urls/base.py", line 86, in reverse
    return resolver._reverse_with_prefix(view, prefix, *args, **kwargs)
  File "/usr/local/lib/python3.8/dist-packages/django/urls/resolvers.py", line 694, in _reverse_with_prefix
    raise NoReverseMatch(msg)
django.urls.exceptions.NoReverseMatch: Reverse for '' not found. '' is not a valid view function or pattern name.
ERROR:django.request:Internal Server Error: /listing_detail/
Traceback (most recent call last):
  File "/usr/local/lib/python3.8/dist-packages/django/core/handlers/exception.py", line 47, in inner
    response = get_response(request)
  File "/usr/local/lib/python3.8/dist-packages/django/core/handlers/base.py", line 181, in _get_response
    response = wrapped_callback(request, *callback_args, **callback_kwargs)
  File "/usr/local/lib/python3.8/dist-packages/django/contrib/auth/decorators.py", line 21, in _wrapped_view
    return view_func(request, *args, **kwargs)
  File "/Anty/main/Anty/views/listing.py", line 73, in listing_detail
    return redirect("")
  File "/usr/local/lib/python3.8/dist-packages/django/shortcuts.py", line 41, in redirect
    return redirect_class(resolve_url(to, *args, **kwargs))
  File "/usr/local/lib/python3.8/dist-packages/django/shortcuts.py", line 130, in resolve_url
    return reverse(to, args=args, kwargs=kwargs)
  File "/usr/local/lib/python3.8/dist-packages/django/urls/base.py", line 86, in reverse
    return resolver._reverse_with_prefix(view, prefix, *args, **kwargs)
  File "/usr/local/lib/python3.8/dist-packages/django/urls/resolvers.py", line 694, in _reverse_with_prefix
    raise NoReverseMatch(msg)
django.urls.exceptions.NoReverseMatch: Reverse for '' not found. '' is not a valid view function or pattern name.
ERROR:django.request:Internal Server Error: /listing_detail/
Traceback (most recent call last):
  File "/usr/local/lib/python3.8/dist-packages/django/core/handlers/exception.py", line 47, in inner
    response = get_response(request)
  File "/usr/local/lib/python3.8/dist-packages/django/core/handlers/base.py", line 181, in _get_response
    response = wrapped_callback(request, *callback_args, **callback_kwargs)
  File "/usr/local/lib/python3.8/dist-packages/django/contrib/auth/decorators.py", line 21, in _wrapped_view
    return view_func(request, *args, **kwargs)
  File "/Anty/main/Anty/views/listing.py", line 73, in listing_detail
    return redirect("")
  File "/usr/local/lib/python3.8/dist-packages/django/shortcuts.py", line 41, in redirect
    return redirect_class(resolve_url(to, *args, **kwargs))
  File "/usr/local/lib/python3.8/dist-packages/django/shortcuts.py", line 130, in resolve_url
    return reverse(to, args=args, kwargs=kwargs)
  File "/usr/local/lib/python3.8/dist-packages/django/urls/base.py", line 86, in reverse
    return resolver._reverse_with_prefix(view, prefix, *args, **kwargs)
  File "/usr/local/lib/python3.8/dist-packages/django/urls/resolvers.py", line 694, in _reverse_with_prefix
    raise NoReverseMatch(msg)
django.urls.exceptions.NoReverseMatch: Reverse for '' not found. '' is not a valid view function or pattern name.
ERROR:django.request:Internal Server Error: /listing_detail/
Traceback (most recent call last):
  File "/usr/local/lib/python3.8/dist-packages/django/core/handlers/exception.py", line 47, in inner
    response = get_response(request)
  File "/usr/local/lib/python3.8/dist-packages/django/core/handlers/base.py", line 181, in _get_response
    response = wrapped_callback(request, *callback_args, **callback_kwargs)
  File "/usr/local/lib/python3.8/dist-packages/django/contrib/auth/decorators.py", line 21, in _wrapped_view
    return view_func(request, *args, **kwargs)
  File "/Anty/main/Anty/views/listing.py", line 73, in listing_detail
    return redirect("")
  File "/usr/local/lib/python3.8/dist-packages/django/shortcuts.py", line 41, in redirect
    return redirect_class(resolve_url(to, *args, **kwargs))
  File "/usr/local/lib/python3.8/dist-packages/django/shortcuts.py", line 130, in resolve_url
    return reverse(to, args=args, kwargs=kwargs)
  File "/usr/local/lib/python3.8/dist-packages/django/urls/base.py", line 86, in reverse
    return resolver._reverse_with_prefix(view, prefix, *args, **kwargs)
  File "/usr/local/lib/python3.8/dist-packages/django/urls/resolvers.py", line 694, in _reverse_with_prefix
    raise NoReverseMatch(msg)
django.urls.exceptions.NoReverseMatch: Reverse for '' not found. '' is not a valid view function or pattern name.
WARNING:django.request:Not Found: /images/iconmonstr-help-2-240 1.png
ERROR:django.request:Internal Server Error: /listing_detail/
Traceback (most recent call last):
  File "/usr/local/lib/python3.8/dist-packages/django/core/handlers/exception.py", line 47, in inner
    response = get_response(request)
  File "/usr/local/lib/python3.8/dist-packages/django/core/handlers/base.py", line 181, in _get_response
    response = wrapped_callback(request, *callback_args, **callback_kwargs)
  File "/usr/local/lib/python3.8/dist-packages/django/contrib/auth/decorators.py", line 21, in _wrapped_view
    return view_func(request, *args, **kwargs)
  File "/Anty/main/Anty/views/listing.py", line 73, in listing_detail
    return redirect("")
  File "/usr/local/lib/python3.8/dist-packages/django/shortcuts.py", line 41, in redirect
    return redirect_class(resolve_url(to, *args, **kwargs))
  File "/usr/local/lib/python3.8/dist-packages/django/shortcuts.py", line 130, in resolve_url
    return reverse(to, args=args, kwargs=kwargs)
  File "/usr/local/lib/python3.8/dist-packages/django/urls/base.py", line 86, in reverse
    return resolver._reverse_with_prefix(view, prefix, *args, **kwargs)
  File "/usr/local/lib/python3.8/dist-packages/django/urls/resolvers.py", line 694, in _reverse_with_prefix
    raise NoReverseMatch(msg)
django.urls.exceptions.NoReverseMatch: Reverse for '' not found. '' is not a valid view function or pattern name.
WARNING:django.request:Not Found: /images/iconmonstr-help-2-240 1.png
ERROR:django.request:Internal Server Error: /listing_detail/
Traceback (most recent call last):
  File "/usr/local/lib/python3.8/dist-packages/django/core/handlers/exception.py", line 47, in inner
    response = get_response(request)
  File "/usr/local/lib/python3.8/dist-packages/django/core/handlers/base.py", line 181, in _get_response
    response = wrapped_callback(request, *callback_args, **callback_kwargs)
  File "/usr/local/lib/python3.8/dist-packages/django/contrib/auth/decorators.py", line 21, in _wrapped_view
    return view_func(request, *args, **kwargs)
  File "/Anty/main/Anty/views/listing.py", line 73, in listing_detail
    return redirect("")
  File "/usr/local/lib/python3.8/dist-packages/django/shortcuts.py", line 41, in redirect
    return redirect_class(resolve_url(to, *args, **kwargs))
  File "/usr/local/lib/python3.8/dist-packages/django/shortcuts.py", line 130, in resolve_url
    return reverse(to, args=args, kwargs=kwargs)
  File "/usr/local/lib/python3.8/dist-packages/django/urls/base.py", line 86, in reverse
    return resolver._reverse_with_prefix(view, prefix, *args, **kwargs)
  File "/usr/local/lib/python3.8/dist-packages/django/urls/resolvers.py", line 694, in _reverse_with_prefix
    raise NoReverseMatch(msg)
django.urls.exceptions.NoReverseMatch: Reverse for '' not found. '' is not a valid view function or pattern name.
WARNING:django.request:Not Found: /images/iconmonstr-help-2-240 1.png
ERROR:django.request:Internal Server Error: /listing_detail/
Traceback (most recent call last):
  File "/usr/local/lib/python3.8/dist-packages/django/core/handlers/exception.py", line 47, in inner
    response = get_response(request)
  File "/usr/local/lib/python3.8/dist-packages/django/core/handlers/base.py", line 181, in _get_response
    response = wrapped_callback(request, *callback_args, **callback_kwargs)
  File "/usr/local/lib/python3.8/dist-packages/django/contrib/auth/decorators.py", line 21, in _wrapped_view
    return view_func(request, *args, **kwargs)
  File "/Anty/main/Anty/views/listing.py", line 73, in listing_detail
    return redirect("")
  File "/usr/local/lib/python3.8/dist-packages/django/shortcuts.py", line 41, in redirect
    return redirect_class(resolve_url(to, *args, **kwargs))
  File "/usr/local/lib/python3.8/dist-packages/django/shortcuts.py", line 130, in resolve_url
    return reverse(to, args=args, kwargs=kwargs)
  File "/usr/local/lib/python3.8/dist-packages/django/urls/base.py", line 86, in reverse
    return resolver._reverse_with_prefix(view, prefix, *args, **kwargs)
  File "/usr/local/lib/python3.8/dist-packages/django/urls/resolvers.py", line 694, in _reverse_with_prefix
    raise NoReverseMatch(msg)
django.urls.exceptions.NoReverseMatch: Reverse for '' not found. '' is not a valid view function or pattern name.
INFO:django.utils.autoreload:/Anty/main/Anty/views/listing.py changed, reloading.
ERROR:django.request:Internal Server Error: /listing_detail/
Traceback (most recent call last):
  File "/usr/local/lib/python3.8/dist-packages/django/core/handlers/exception.py", line 47, in inner
    response = get_response(request)
  File "/usr/local/lib/python3.8/dist-packages/django/core/handlers/base.py", line 181, in _get_response
    response = wrapped_callback(request, *callback_args, **callback_kwargs)
  File "/usr/local/lib/python3.8/dist-packages/django/contrib/auth/decorators.py", line 21, in _wrapped_view
    return view_func(request, *args, **kwargs)
  File "/Anty/main/Anty/views/listing.py", line 74, in listing_detail
    return redirect("")
  File "/usr/local/lib/python3.8/dist-packages/django/shortcuts.py", line 41, in redirect
    return redirect_class(resolve_url(to, *args, **kwargs))
  File "/usr/local/lib/python3.8/dist-packages/django/shortcuts.py", line 130, in resolve_url
    return reverse(to, args=args, kwargs=kwargs)
  File "/usr/local/lib/python3.8/dist-packages/django/urls/base.py", line 86, in reverse
    return resolver._reverse_with_prefix(view, prefix, *args, **kwargs)
  File "/usr/local/lib/python3.8/dist-packages/django/urls/resolvers.py", line 694, in _reverse_with_prefix
    raise NoReverseMatch(msg)
django.urls.exceptions.NoReverseMatch: Reverse for '' not found. '' is not a valid view function or pattern name.
ERROR:django.request:Internal Server Error: /listing_detail/
Traceback (most recent call last):
  File "/usr/local/lib/python3.8/dist-packages/django/core/handlers/exception.py", line 47, in inner
    response = get_response(request)
  File "/usr/local/lib/python3.8/dist-packages/django/core/handlers/base.py", line 181, in _get_response
    response = wrapped_callback(request, *callback_args, **callback_kwargs)
  File "/usr/local/lib/python3.8/dist-packages/django/contrib/auth/decorators.py", line 21, in _wrapped_view
    return view_func(request, *args, **kwargs)
  File "/Anty/main/Anty/views/listing.py", line 74, in listing_detail
    return redirect("")
  File "/usr/local/lib/python3.8/dist-packages/django/shortcuts.py", line 41, in redirect
    return redirect_class(resolve_url(to, *args, **kwargs))
  File "/usr/local/lib/python3.8/dist-packages/django/shortcuts.py", line 130, in resolve_url
    return reverse(to, args=args, kwargs=kwargs)
  File "/usr/local/lib/python3.8/dist-packages/django/urls/base.py", line 86, in reverse
    return resolver._reverse_with_prefix(view, prefix, *args, **kwargs)
  File "/usr/local/lib/python3.8/dist-packages/django/urls/resolvers.py", line 694, in _reverse_with_prefix
    raise NoReverseMatch(msg)
django.urls.exceptions.NoReverseMatch: Reverse for '' not found. '' is not a valid view function or pattern name.
WARNING:django.request:Not Found: /images/iconmonstr-help-2-240 1.png
WARNING:django.request:Not Found: /favicon.ico
ERROR:django.request:Internal Server Error: /listing_detail/
Traceback (most recent call last):
  File "/usr/local/lib/python3.8/dist-packages/django/core/handlers/exception.py", line 47, in inner
    response = get_response(request)
  File "/usr/local/lib/python3.8/dist-packages/django/core/handlers/base.py", line 181, in _get_response
    response = wrapped_callback(request, *callback_args, **callback_kwargs)
  File "/usr/local/lib/python3.8/dist-packages/django/contrib/auth/decorators.py", line 21, in _wrapped_view
    return view_func(request, *args, **kwargs)
  File "/Anty/main/Anty/views/listing.py", line 74, in listing_detail
    return redirect("")
  File "/usr/local/lib/python3.8/dist-packages/django/shortcuts.py", line 41, in redirect
    return redirect_class(resolve_url(to, *args, **kwargs))
  File "/usr/local/lib/python3.8/dist-packages/django/shortcuts.py", line 130, in resolve_url
    return reverse(to, args=args, kwargs=kwargs)
  File "/usr/local/lib/python3.8/dist-packages/django/urls/base.py", line 86, in reverse
    return resolver._reverse_with_prefix(view, prefix, *args, **kwargs)
  File "/usr/local/lib/python3.8/dist-packages/django/urls/resolvers.py", line 694, in _reverse_with_prefix
    raise NoReverseMatch(msg)
django.urls.exceptions.NoReverseMatch: Reverse for '' not found. '' is not a valid view function or pattern name.
WARNING:django.request:Not Found: /images/iconmonstr-help-2-240 1.png
INFO:django.utils.autoreload:/Anty/main/Anty/views/listing.py changed, reloading.
ERROR:django.request:Internal Server Error: /listing_detail/
Traceback (most recent call last):
  File "/usr/local/lib/python3.8/dist-packages/django/core/handlers/exception.py", line 47, in inner
    response = get_response(request)
  File "/usr/local/lib/python3.8/dist-packages/django/core/handlers/base.py", line 181, in _get_response
    response = wrapped_callback(request, *callback_args, **callback_kwargs)
  File "/usr/local/lib/python3.8/dist-packages/django/contrib/auth/decorators.py", line 21, in _wrapped_view
    return view_func(request, *args, **kwargs)
  File "/Anty/main/Anty/views/listing.py", line 74, in listing_detail
    return redirect("")
  File "/usr/local/lib/python3.8/dist-packages/django/shortcuts.py", line 41, in redirect
    return redirect_class(resolve_url(to, *args, **kwargs))
  File "/usr/local/lib/python3.8/dist-packages/django/shortcuts.py", line 130, in resolve_url
    return reverse(to, args=args, kwargs=kwargs)
  File "/usr/local/lib/python3.8/dist-packages/django/urls/base.py", line 86, in reverse
    return resolver._reverse_with_prefix(view, prefix, *args, **kwargs)
  File "/usr/local/lib/python3.8/dist-packages/django/urls/resolvers.py", line 694, in _reverse_with_prefix
    raise NoReverseMatch(msg)
django.urls.exceptions.NoReverseMatch: Reverse for '' not found. '' is not a valid view function or pattern name.
WARNING:django.request:Not Found: /images/iconmonstr-help-2-240 1.png
ERROR:django.request:Internal Server Error: /listing_detail/
Traceback (most recent call last):
  File "/usr/local/lib/python3.8/dist-packages/django/core/handlers/exception.py", line 47, in inner
    response = get_response(request)
  File "/usr/local/lib/python3.8/dist-packages/django/core/handlers/base.py", line 181, in _get_response
    response = wrapped_callback(request, *callback_args, **callback_kwargs)
  File "/usr/local/lib/python3.8/dist-packages/django/contrib/auth/decorators.py", line 21, in _wrapped_view
    return view_func(request, *args, **kwargs)
  File "/Anty/main/Anty/views/listing.py", line 74, in listing_detail
    return redirect("")
  File "/usr/local/lib/python3.8/dist-packages/django/shortcuts.py", line 41, in redirect
    return redirect_class(resolve_url(to, *args, **kwargs))
  File "/usr/local/lib/python3.8/dist-packages/django/shortcuts.py", line 130, in resolve_url
    return reverse(to, args=args, kwargs=kwargs)
  File "/usr/local/lib/python3.8/dist-packages/django/urls/base.py", line 86, in reverse
    return resolver._reverse_with_prefix(view, prefix, *args, **kwargs)
  File "/usr/local/lib/python3.8/dist-packages/django/urls/resolvers.py", line 694, in _reverse_with_prefix
    raise NoReverseMatch(msg)
django.urls.exceptions.NoReverseMatch: Reverse for '' not found. '' is not a valid view function or pattern name.
WARNING:django.request:Not Found: /images/iconmonstr-help-2-240 1.png
ERROR:django.request:Internal Server Error: /listing_detail/
Traceback (most recent call last):
  File "/usr/local/lib/python3.8/dist-packages/django/core/handlers/exception.py", line 47, in inner
    response = get_response(request)
  File "/usr/local/lib/python3.8/dist-packages/django/core/handlers/base.py", line 181, in _get_response
    response = wrapped_callback(request, *callback_args, **callback_kwargs)
  File "/usr/local/lib/python3.8/dist-packages/django/contrib/auth/decorators.py", line 21, in _wrapped_view
    return view_func(request, *args, **kwargs)
  File "/Anty/main/Anty/views/listing.py", line 74, in listing_detail
    return redirect("")
  File "/usr/local/lib/python3.8/dist-packages/django/shortcuts.py", line 41, in redirect
    return redirect_class(resolve_url(to, *args, **kwargs))
  File "/usr/local/lib/python3.8/dist-packages/django/shortcuts.py", line 130, in resolve_url
    return reverse(to, args=args, kwargs=kwargs)
  File "/usr/local/lib/python3.8/dist-packages/django/urls/base.py", line 86, in reverse
    return resolver._reverse_with_prefix(view, prefix, *args, **kwargs)
  File "/usr/local/lib/python3.8/dist-packages/django/urls/resolvers.py", line 694, in _reverse_with_prefix
    raise NoReverseMatch(msg)
django.urls.exceptions.NoReverseMatch: Reverse for '' not found. '' is not a valid view function or pattern name.
INFO:django.utils.autoreload:/Anty/main/Anty/views/listing.py changed, reloading.
ERROR:django.request:Internal Server Error: /listing_detail/
Traceback (most recent call last):
  File "/usr/local/lib/python3.8/dist-packages/django/utils/datastructures.py", line 76, in __getitem__
    list_ = super().__getitem__(key)
KeyError: 'image_1'

During handling of the above exception, another exception occurred:

Traceback (most recent call last):
  File "/usr/local/lib/python3.8/dist-packages/django/core/handlers/exception.py", line 47, in inner
    response = get_response(request)
  File "/usr/local/lib/python3.8/dist-packages/django/core/handlers/base.py", line 181, in _get_response
    response = wrapped_callback(request, *callback_args, **callback_kwargs)
  File "/usr/local/lib/python3.8/dist-packages/django/contrib/auth/decorators.py", line 21, in _wrapped_view
    return view_func(request, *args, **kwargs)
  File "/Anty/main/Anty/views/listing.py", line 65, in listing_detail
    print (request.FILES["image_1"])
  File "/usr/local/lib/python3.8/dist-packages/django/utils/datastructures.py", line 78, in __getitem__
    raise MultiValueDictKeyError(key)
django.utils.datastructures.MultiValueDictKeyError: 'image_1'
WARNING:django.request:Not Found: /images/iconmonstr-help-2-240 1.png
ERROR:django.request:Internal Server Error: /listing_detail/
Traceback (most recent call last):
  File "/usr/local/lib/python3.8/dist-packages/django/utils/datastructures.py", line 76, in __getitem__
    list_ = super().__getitem__(key)
KeyError: 'image_1'

During handling of the above exception, another exception occurred:

Traceback (most recent call last):
  File "/usr/local/lib/python3.8/dist-packages/django/core/handlers/exception.py", line 47, in inner
    response = get_response(request)
  File "/usr/local/lib/python3.8/dist-packages/django/core/handlers/base.py", line 181, in _get_response
    response = wrapped_callback(request, *callback_args, **callback_kwargs)
  File "/usr/local/lib/python3.8/dist-packages/django/contrib/auth/decorators.py", line 21, in _wrapped_view
    return view_func(request, *args, **kwargs)
  File "/Anty/main/Anty/views/listing.py", line 65, in listing_detail
    print (request.FILES["image_1"])
  File "/usr/local/lib/python3.8/dist-packages/django/utils/datastructures.py", line 78, in __getitem__
    raise MultiValueDictKeyError(key)
django.utils.datastructures.MultiValueDictKeyError: 'image_1'
INFO:django.utils.autoreload:/Anty/main/Anty/views/listing.py changed, reloading.
ERROR:django.request:Internal Server Error: /listing_detail/
Traceback (most recent call last):
  File "/usr/local/lib/python3.8/dist-packages/django/utils/datastructures.py", line 76, in __getitem__
    list_ = super().__getitem__(key)
KeyError: 'image_1'

During handling of the above exception, another exception occurred:

Traceback (most recent call last):
  File "/usr/local/lib/python3.8/dist-packages/django/core/handlers/exception.py", line 47, in inner
    response = get_response(request)
  File "/usr/local/lib/python3.8/dist-packages/django/core/handlers/base.py", line 181, in _get_response
    response = wrapped_callback(request, *callback_args, **callback_kwargs)
  File "/usr/local/lib/python3.8/dist-packages/django/contrib/auth/decorators.py", line 21, in _wrapped_view
    return view_func(request, *args, **kwargs)
  File "/Anty/main/Anty/views/listing.py", line 65, in listing_detail
    print (request.FILES["image_1"])
  File "/usr/local/lib/python3.8/dist-packages/django/utils/datastructures.py", line 78, in __getitem__
    raise MultiValueDictKeyError(key)
django.utils.datastructures.MultiValueDictKeyError: 'image_1'
ERROR:django.request:Internal Server Error: /listing_detail/
Traceback (most recent call last):
  File "/usr/local/lib/python3.8/dist-packages/django/utils/datastructures.py", line 76, in __getitem__
    list_ = super().__getitem__(key)
KeyError: 'image_1'

During handling of the above exception, another exception occurred:

Traceback (most recent call last):
  File "/usr/local/lib/python3.8/dist-packages/django/core/handlers/exception.py", line 47, in inner
    response = get_response(request)
  File "/usr/local/lib/python3.8/dist-packages/django/core/handlers/base.py", line 181, in _get_response
    response = wrapped_callback(request, *callback_args, **callback_kwargs)
  File "/usr/local/lib/python3.8/dist-packages/django/contrib/auth/decorators.py", line 21, in _wrapped_view
    return view_func(request, *args, **kwargs)
  File "/Anty/main/Anty/views/listing.py", line 65, in listing_detail
    print (request.FILES["image_1"])
  File "/usr/local/lib/python3.8/dist-packages/django/utils/datastructures.py", line 78, in __getitem__
    raise MultiValueDictKeyError(key)
django.utils.datastructures.MultiValueDictKeyError: 'image_1'
WARNING:django.request:Not Found: /images/iconmonstr-help-2-240 1.png
ERROR:django.request:Internal Server Error: /listing_detail/
Traceback (most recent call last):
  File "/usr/local/lib/python3.8/dist-packages/django/utils/datastructures.py", line 76, in __getitem__
    list_ = super().__getitem__(key)
KeyError: 'image_1'

During handling of the above exception, another exception occurred:

Traceback (most recent call last):
  File "/usr/local/lib/python3.8/dist-packages/django/core/handlers/exception.py", line 47, in inner
    response = get_response(request)
  File "/usr/local/lib/python3.8/dist-packages/django/core/handlers/base.py", line 181, in _get_response
    response = wrapped_callback(request, *callback_args, **callback_kwargs)
  File "/usr/local/lib/python3.8/dist-packages/django/contrib/auth/decorators.py", line 21, in _wrapped_view
    return view_func(request, *args, **kwargs)
  File "/Anty/main/Anty/views/listing.py", line 65, in listing_detail
    print (request.FILES["image_1"])
  File "/usr/local/lib/python3.8/dist-packages/django/utils/datastructures.py", line 78, in __getitem__
    raise MultiValueDictKeyError(key)
django.utils.datastructures.MultiValueDictKeyError: 'image_1'
INFO:django.utils.autoreload:/Anty/main/Anty/views/listing.py changed, reloading.
ERROR:django.request:Internal Server Error: /listing_detail/
Traceback (most recent call last):
  File "/usr/local/lib/python3.8/dist-packages/django/core/handlers/exception.py", line 47, in inner
    response = get_response(request)
  File "/usr/local/lib/python3.8/dist-packages/django/core/handlers/base.py", line 181, in _get_response
    response = wrapped_callback(request, *callback_args, **callback_kwargs)
  File "/usr/local/lib/python3.8/dist-packages/django/contrib/auth/decorators.py", line 21, in _wrapped_view
    return view_func(request, *args, **kwargs)
  File "/Anty/main/Anty/views/listing.py", line 74, in listing_detail
    return redirect("")
  File "/usr/local/lib/python3.8/dist-packages/django/shortcuts.py", line 41, in redirect
    return redirect_class(resolve_url(to, *args, **kwargs))
  File "/usr/local/lib/python3.8/dist-packages/django/shortcuts.py", line 130, in resolve_url
    return reverse(to, args=args, kwargs=kwargs)
  File "/usr/local/lib/python3.8/dist-packages/django/urls/base.py", line 86, in reverse
    return resolver._reverse_with_prefix(view, prefix, *args, **kwargs)
  File "/usr/local/lib/python3.8/dist-packages/django/urls/resolvers.py", line 694, in _reverse_with_prefix
    raise NoReverseMatch(msg)
django.urls.exceptions.NoReverseMatch: Reverse for '' not found. '' is not a valid view function or pattern name.
WARNING:django.request:Not Found: /images/iconmonstr-help-2-240 1.png
ERROR:django.request:Internal Server Error: /listing_detail/
Traceback (most recent call last):
  File "/usr/local/lib/python3.8/dist-packages/django/core/handlers/exception.py", line 47, in inner
    response = get_response(request)
  File "/usr/local/lib/python3.8/dist-packages/django/core/handlers/base.py", line 181, in _get_response
    response = wrapped_callback(request, *callback_args, **callback_kwargs)
  File "/usr/local/lib/python3.8/dist-packages/django/contrib/auth/decorators.py", line 21, in _wrapped_view
    return view_func(request, *args, **kwargs)
  File "/Anty/main/Anty/views/listing.py", line 74, in listing_detail
    return redirect("")
  File "/usr/local/lib/python3.8/dist-packages/django/shortcuts.py", line 41, in redirect
    return redirect_class(resolve_url(to, *args, **kwargs))
  File "/usr/local/lib/python3.8/dist-packages/django/shortcuts.py", line 130, in resolve_url
    return reverse(to, args=args, kwargs=kwargs)
  File "/usr/local/lib/python3.8/dist-packages/django/urls/base.py", line 86, in reverse
    return resolver._reverse_with_prefix(view, prefix, *args, **kwargs)
  File "/usr/local/lib/python3.8/dist-packages/django/urls/resolvers.py", line 694, in _reverse_with_prefix
    raise NoReverseMatch(msg)
django.urls.exceptions.NoReverseMatch: Reverse for '' not found. '' is not a valid view function or pattern name.
INFO:django.utils.autoreload:/Anty/main/main/settings.py changed, reloading.
INFO:django.utils.autoreload:/Anty/main/Anty/views/listing.py changed, reloading.
WARNING:django.security.csrf:Forbidden (CSRF token missing or incorrect.): /listing_detail/
ERROR:django.request:Internal Server Error: /listing_detail/
Traceback (most recent call last):
  File "/usr/local/lib/python3.8/dist-packages/django/core/handlers/exception.py", line 47, in inner
    response = get_response(request)
  File "/usr/local/lib/python3.8/dist-packages/django/core/handlers/base.py", line 181, in _get_response
    response = wrapped_callback(request, *callback_args, **callback_kwargs)
  File "/usr/local/lib/python3.8/dist-packages/django/contrib/auth/decorators.py", line 21, in _wrapped_view
    return view_func(request, *args, **kwargs)
  File "/Anty/main/Anty/views/listing.py", line 74, in listing_detail
    return redirect("")
  File "/usr/local/lib/python3.8/dist-packages/django/shortcuts.py", line 41, in redirect
    return redirect_class(resolve_url(to, *args, **kwargs))
  File "/usr/local/lib/python3.8/dist-packages/django/shortcuts.py", line 130, in resolve_url
    return reverse(to, args=args, kwargs=kwargs)
  File "/usr/local/lib/python3.8/dist-packages/django/urls/base.py", line 86, in reverse
    return resolver._reverse_with_prefix(view, prefix, *args, **kwargs)
  File "/usr/local/lib/python3.8/dist-packages/django/urls/resolvers.py", line 694, in _reverse_with_prefix
    raise NoReverseMatch(msg)
django.urls.exceptions.NoReverseMatch: Reverse for '' not found. '' is not a valid view function or pattern name.
INFO:django.utils.autoreload:/Anty/main/Anty/views/listing.py changed, reloading.
ERROR:django.request:Internal Server Error: /listing_detail/
Traceback (most recent call last):
  File "/usr/local/lib/python3.8/dist-packages/django/core/handlers/exception.py", line 47, in inner
    response = get_response(request)
  File "/usr/local/lib/python3.8/dist-packages/django/core/handlers/base.py", line 181, in _get_response
    response = wrapped_callback(request, *callback_args, **callback_kwargs)
  File "/usr/local/lib/python3.8/dist-packages/django/contrib/auth/decorators.py", line 21, in _wrapped_view
    return view_func(request, *args, **kwargs)
  File "/Anty/main/Anty/views/listing.py", line 74, in listing_detail
    return redirect("")
  File "/usr/local/lib/python3.8/dist-packages/django/shortcuts.py", line 41, in redirect
    return redirect_class(resolve_url(to, *args, **kwargs))
  File "/usr/local/lib/python3.8/dist-packages/django/shortcuts.py", line 130, in resolve_url
    return reverse(to, args=args, kwargs=kwargs)
  File "/usr/local/lib/python3.8/dist-packages/django/urls/base.py", line 86, in reverse
    return resolver._reverse_with_prefix(view, prefix, *args, **kwargs)
  File "/usr/local/lib/python3.8/dist-packages/django/urls/resolvers.py", line 694, in _reverse_with_prefix
    raise NoReverseMatch(msg)
django.urls.exceptions.NoReverseMatch: Reverse for '' not found. '' is not a valid view function or pattern name.
INFO:django.utils.autoreload:/Anty/main/Anty/views/listing.py changed, reloading.
ERROR:django.request:Internal Server Error: /listing_detail/
Traceback (most recent call last):
  File "/usr/local/lib/python3.8/dist-packages/django/core/handlers/exception.py", line 47, in inner
    response = get_response(request)
  File "/usr/local/lib/python3.8/dist-packages/django/core/handlers/base.py", line 181, in _get_response
    response = wrapped_callback(request, *callback_args, **callback_kwargs)
  File "/usr/local/lib/python3.8/dist-packages/django/contrib/auth/decorators.py", line 21, in _wrapped_view
    return view_func(request, *args, **kwargs)
  File "/Anty/main/Anty/views/listing.py", line 74, in listing_detail
    return redirect("")
  File "/usr/local/lib/python3.8/dist-packages/django/shortcuts.py", line 41, in redirect
    return redirect_class(resolve_url(to, *args, **kwargs))
  File "/usr/local/lib/python3.8/dist-packages/django/shortcuts.py", line 130, in resolve_url
    return reverse(to, args=args, kwargs=kwargs)
  File "/usr/local/lib/python3.8/dist-packages/django/urls/base.py", line 86, in reverse
    return resolver._reverse_with_prefix(view, prefix, *args, **kwargs)
  File "/usr/local/lib/python3.8/dist-packages/django/urls/resolvers.py", line 694, in _reverse_with_prefix
    raise NoReverseMatch(msg)
django.urls.exceptions.NoReverseMatch: Reverse for '' not found. '' is not a valid view function or pattern name.
INFO:django.utils.autoreload:/Anty/main/Anty/views/listing.py changed, reloading.
ERROR:django.request:Internal Server Error: /listing_detail/
Traceback (most recent call last):
  File "/usr/local/lib/python3.8/dist-packages/django/core/handlers/exception.py", line 47, in inner
    response = get_response(request)
  File "/usr/local/lib/python3.8/dist-packages/django/core/handlers/base.py", line 181, in _get_response
    response = wrapped_callback(request, *callback_args, **callback_kwargs)
  File "/usr/local/lib/python3.8/dist-packages/django/contrib/auth/decorators.py", line 21, in _wrapped_view
    return view_func(request, *args, **kwargs)
  File "/Anty/main/Anty/views/listing.py", line 60, in listing_detail
    print (request.CONTENT_TYPE)
AttributeError: 'WSGIRequest' object has no attribute 'CONTENT_TYPE'
INFO:django.utils.autoreload:/Anty/main/Anty/views/listing.py changed, reloading.
ERROR:django.request:Internal Server Error: /listing_detail/
Traceback (most recent call last):
  File "/usr/local/lib/python3.8/dist-packages/django/core/handlers/exception.py", line 47, in inner
    response = get_response(request)
  File "/usr/local/lib/python3.8/dist-packages/django/core/handlers/base.py", line 181, in _get_response
    response = wrapped_callback(request, *callback_args, **callback_kwargs)
  File "/usr/local/lib/python3.8/dist-packages/django/contrib/auth/decorators.py", line 21, in _wrapped_view
    return view_func(request, *args, **kwargs)
  File "/Anty/main/Anty/views/listing.py", line 60, in listing_detail
    print (request.META.CONTENT_TYPE)
AttributeError: 'dict' object has no attribute 'CONTENT_TYPE'
INFO:django.utils.autoreload:/Anty/main/Anty/views/listing.py changed, reloading.
ERROR:django.request:Internal Server Error: /listing_detail/
Traceback (most recent call last):
  File "/usr/local/lib/python3.8/dist-packages/django/core/handlers/exception.py", line 47, in inner
    response = get_response(request)
  File "/usr/local/lib/python3.8/dist-packages/django/core/handlers/base.py", line 181, in _get_response
    response = wrapped_callback(request, *callback_args, **callback_kwargs)
  File "/usr/local/lib/python3.8/dist-packages/django/contrib/auth/decorators.py", line 21, in _wrapped_view
    return view_func(request, *args, **kwargs)
  File "/Anty/main/Anty/views/listing.py", line 74, in listing_detail
    return redirect("")
  File "/usr/local/lib/python3.8/dist-packages/django/shortcuts.py", line 41, in redirect
    return redirect_class(resolve_url(to, *args, **kwargs))
  File "/usr/local/lib/python3.8/dist-packages/django/shortcuts.py", line 130, in resolve_url
    return reverse(to, args=args, kwargs=kwargs)
  File "/usr/local/lib/python3.8/dist-packages/django/urls/base.py", line 86, in reverse
    return resolver._reverse_with_prefix(view, prefix, *args, **kwargs)
  File "/usr/local/lib/python3.8/dist-packages/django/urls/resolvers.py", line 694, in _reverse_with_prefix
    raise NoReverseMatch(msg)
django.urls.exceptions.NoReverseMatch: Reverse for '' not found. '' is not a valid view function or pattern name.
INFO:django.utils.autoreload:/Anty/main/Anty/views/listing.py changed, reloading.
ERROR:django.request:Internal Server Error: /listing_detail/
Traceback (most recent call last):
  File "/usr/local/lib/python3.8/dist-packages/django/core/handlers/exception.py", line 47, in inner
    response = get_response(request)
  File "/usr/local/lib/python3.8/dist-packages/django/core/handlers/base.py", line 181, in _get_response
    response = wrapped_callback(request, *callback_args, **callback_kwargs)
  File "/usr/local/lib/python3.8/dist-packages/django/contrib/auth/decorators.py", line 21, in _wrapped_view
    return view_func(request, *args, **kwargs)
  File "/Anty/main/Anty/views/listing.py", line 73, in listing_detail
    return redirect("")
  File "/usr/local/lib/python3.8/dist-packages/django/shortcuts.py", line 41, in redirect
    return redirect_class(resolve_url(to, *args, **kwargs))
  File "/usr/local/lib/python3.8/dist-packages/django/shortcuts.py", line 130, in resolve_url
    return reverse(to, args=args, kwargs=kwargs)
  File "/usr/local/lib/python3.8/dist-packages/django/urls/base.py", line 86, in reverse
    return resolver._reverse_with_prefix(view, prefix, *args, **kwargs)
  File "/usr/local/lib/python3.8/dist-packages/django/urls/resolvers.py", line 694, in _reverse_with_prefix
    raise NoReverseMatch(msg)
django.urls.exceptions.NoReverseMatch: Reverse for '' not found. '' is not a valid view function or pattern name.
INFO:django.utils.autoreload:/Anty/main/Anty/views/listing.py changed, reloading.
ERROR:django.request:Internal Server Error: /listing_detail/
Traceback (most recent call last):
  File "/usr/local/lib/python3.8/dist-packages/django/core/handlers/exception.py", line 47, in inner
    response = get_response(request)
  File "/usr/local/lib/python3.8/dist-packages/django/core/handlers/base.py", line 181, in _get_response
    response = wrapped_callback(request, *callback_args, **callback_kwargs)
  File "/usr/local/lib/python3.8/dist-packages/django/contrib/auth/decorators.py", line 21, in _wrapped_view
    return view_func(request, *args, **kwargs)
  File "/Anty/main/Anty/views/listing.py", line 73, in listing_detail
    return redirect("")
  File "/usr/local/lib/python3.8/dist-packages/django/shortcuts.py", line 41, in redirect
    return redirect_class(resolve_url(to, *args, **kwargs))
  File "/usr/local/lib/python3.8/dist-packages/django/shortcuts.py", line 130, in resolve_url
    return reverse(to, args=args, kwargs=kwargs)
  File "/usr/local/lib/python3.8/dist-packages/django/urls/base.py", line 86, in reverse
    return resolver._reverse_with_prefix(view, prefix, *args, **kwargs)
  File "/usr/local/lib/python3.8/dist-packages/django/urls/resolvers.py", line 694, in _reverse_with_prefix
    raise NoReverseMatch(msg)
django.urls.exceptions.NoReverseMatch: Reverse for '' not found. '' is not a valid view function or pattern name.
INFO:django.utils.autoreload:/Anty/main/Anty/views/listing.py changed, reloading.
INFO:django.utils.autoreload:/Anty/main/Anty/views/listing.py changed, reloading.
WARNING:django.request:Not Found: /images/iconmonstr-help-2-240 1.png
WARNING:django.request:Not Found: /images/iconmonstr-help-2-240 1.png
WARNING:django.request:Not Found: /images/iconmonstr-help-2-240 1.png
WARNING:django.request:Not Found: /images/iconmonstr-help-2-240 1.png
WARNING:django.request:Not Found: /images/iconmonstr-help-2-240 1.png
WARNING:django.request:Not Found: /images/iconmonstr-help-2-240 1.png
WARNING:django.request:Not Found: /images/iconmonstr-help-2-240 1.png
ERROR:django.request:Internal Server Error: /listing_detail/
Traceback (most recent call last):
  File "/usr/local/lib/python3.8/dist-packages/django/core/handlers/exception.py", line 47, in inner
    response = get_response(request)
  File "/usr/local/lib/python3.8/dist-packages/django/core/handlers/base.py", line 181, in _get_response
    response = wrapped_callback(request, *callback_args, **callback_kwargs)
  File "/usr/local/lib/python3.8/dist-packages/django/contrib/auth/decorators.py", line 21, in _wrapped_view
    return view_func(request, *args, **kwargs)
  File "/Anty/main/Anty/views/listing.py", line 73, in listing_detail
    return redirect("")
  File "/usr/local/lib/python3.8/dist-packages/django/shortcuts.py", line 41, in redirect
    return redirect_class(resolve_url(to, *args, **kwargs))
  File "/usr/local/lib/python3.8/dist-packages/django/shortcuts.py", line 130, in resolve_url
    return reverse(to, args=args, kwargs=kwargs)
  File "/usr/local/lib/python3.8/dist-packages/django/urls/base.py", line 86, in reverse
    return resolver._reverse_with_prefix(view, prefix, *args, **kwargs)
  File "/usr/local/lib/python3.8/dist-packages/django/urls/resolvers.py", line 694, in _reverse_with_prefix
    raise NoReverseMatch(msg)
django.urls.exceptions.NoReverseMatch: Reverse for '' not found. '' is not a valid view function or pattern name.
INFO:django.utils.autoreload:/Anty/main/Anty/views/listing.py changed, reloading.
ERROR:django.request:Internal Server Error: /listing_detail/
Traceback (most recent call last):
  File "/usr/local/lib/python3.8/dist-packages/django/core/handlers/exception.py", line 47, in inner
    response = get_response(request)
  File "/usr/local/lib/python3.8/dist-packages/django/core/handlers/base.py", line 181, in _get_response
    response = wrapped_callback(request, *callback_args, **callback_kwargs)
  File "/usr/local/lib/python3.8/dist-packages/django/contrib/auth/decorators.py", line 21, in _wrapped_view
    return view_func(request, *args, **kwargs)
  File "/Anty/main/Anty/views/listing.py", line 68, in listing_detail
    file_name = fs.save(("temporary_image/"+request.user.id+time.time()), image)
TypeError: can only concatenate str (not "int") to str
INFO:django.utils.autoreload:/Anty/main/Anty/views/listing.py changed, reloading.
ERROR:django.request:Internal Server Error: /listing_detail/
Traceback (most recent call last):
  File "/usr/local/lib/python3.8/dist-packages/django/utils/datastructures.py", line 76, in __getitem__
    list_ = super().__getitem__(key)
KeyError: 'image_2'

During handling of the above exception, another exception occurred:

Traceback (most recent call last):
  File "/usr/local/lib/python3.8/dist-packages/django/core/handlers/exception.py", line 47, in inner
    response = get_response(request)
  File "/usr/local/lib/python3.8/dist-packages/django/core/handlers/base.py", line 181, in _get_response
    response = wrapped_callback(request, *callback_args, **callback_kwargs)
  File "/usr/local/lib/python3.8/dist-packages/django/contrib/auth/decorators.py", line 21, in _wrapped_view
    return view_func(request, *args, **kwargs)
  File "/Anty/main/Anty/views/listing.py", line 64, in listing_detail
    image = request.FILES[str("image_"+str(count))]
  File "/usr/local/lib/python3.8/dist-packages/django/utils/datastructures.py", line 78, in __getitem__
    raise MultiValueDictKeyError(key)
django.utils.datastructures.MultiValueDictKeyError: 'image_2'
INFO:django.utils.autoreload:/Anty/main/Anty/views/listing.py changed, reloading.
INFO:django.utils.autoreload:/Anty/main/Anty/views/listing.py changed, reloading.
ERROR:django.request:Internal Server Error: /
Traceback (most recent call last):
  File "/usr/local/lib/python3.8/dist-packages/django/core/handlers/exception.py", line 47, in inner
    response = get_response(request)
  File "/usr/local/lib/python3.8/dist-packages/django/core/handlers/base.py", line 167, in _get_response
    callback, callback_args, callback_kwargs = self.resolve_request(request)
  File "/usr/local/lib/python3.8/dist-packages/django/core/handlers/base.py", line 290, in resolve_request
    resolver_match = resolver.resolve(request.path_info)
  File "/usr/local/lib/python3.8/dist-packages/django/urls/resolvers.py", line 556, in resolve
    for pattern in self.url_patterns:
  File "/usr/local/lib/python3.8/dist-packages/django/utils/functional.py", line 48, in __get__
    res = instance.__dict__[self.name] = self.func(instance)
  File "/usr/local/lib/python3.8/dist-packages/django/urls/resolvers.py", line 598, in url_patterns
    patterns = getattr(self.urlconf_module, "urlpatterns", self.urlconf_module)
  File "/usr/local/lib/python3.8/dist-packages/django/utils/functional.py", line 48, in __get__
    res = instance.__dict__[self.name] = self.func(instance)
  File "/usr/local/lib/python3.8/dist-packages/django/urls/resolvers.py", line 591, in urlconf_module
    return import_module(self.urlconf_name)
  File "/usr/lib/python3.8/importlib/__init__.py", line 127, in import_module
    return _bootstrap._gcd_import(name[level:], package, level)
  File "<frozen importlib._bootstrap>", line 1014, in _gcd_import
  File "<frozen importlib._bootstrap>", line 991, in _find_and_load
  File "<frozen importlib._bootstrap>", line 975, in _find_and_load_unlocked
  File "<frozen importlib._bootstrap>", line 671, in _load_unlocked
  File "<frozen importlib._bootstrap_external>", line 848, in exec_module
  File "<frozen importlib._bootstrap>", line 219, in _call_with_frames_removed
  File "/Anty/main/main/urls.py", line 4, in <module>
    from Anty.views import main, user, line_bot, listing
  File "/Anty/main/Anty/views/listing.py", line 61
    fs = FileSystemStorage())
                            ^
SyntaxError: unmatched ')'
INFO:django.utils.autoreload:/Anty/main/Anty/views/listing.py changed, reloading.
ERROR:django.security.DisallowedHost:Invalid HTTP_HOST header: ''. The domain name provided is not valid according to RFC 1034/1035.
WARNING:django.request:Bad Request: /manager/html
INFO:django.utils.autoreload:/Anty/main/Anty/views/listing.py changed, reloading.
INFO:django.utils.autoreload:/Anty/main/Anty/views/listing.py changed, reloading.
WARNING:django.request:Not Found: /images/iconmonstr-help-2-240 1.png
ERROR:django.request:Internal Server Error: /listing_detail/
Traceback (most recent call last):
  File "/usr/local/lib/python3.8/dist-packages/django/core/handlers/exception.py", line 47, in inner
    response = get_response(request)
  File "/usr/local/lib/python3.8/dist-packages/django/core/handlers/base.py", line 181, in _get_response
    response = wrapped_callback(request, *callback_args, **callback_kwargs)
  File "/usr/local/lib/python3.8/dist-packages/django/contrib/auth/decorators.py", line 21, in _wrapped_view
    return view_func(request, *args, **kwargs)
  File "/Anty/main/Anty/views/listing.py", line 64, in listing_detail
    ext = image.split(".")[-1]
AttributeError: 'InMemoryUploadedFile' object has no attribute 'split'
INFO:django.utils.autoreload:/Anty/main/Anty/views/listing.py changed, reloading.
INFO:django.utils.autoreload:/Anty/main/Anty/views/listing.py changed, reloading.
INFO:django.utils.autoreload:/Anty/main/Anty/views/listing.py changed, reloading.
ERROR:django.request:Internal Server Error: /listing_detail/
Traceback (most recent call last):
  File "/usr/local/lib/python3.8/dist-packages/django/core/handlers/exception.py", line 47, in inner
    response = get_response(request)
  File "/usr/local/lib/python3.8/dist-packages/django/core/handlers/base.py", line 181, in _get_response
    response = wrapped_callback(request, *callback_args, **callback_kwargs)
  File "/usr/local/lib/python3.8/dist-packages/django/contrib/auth/decorators.py", line 21, in _wrapped_view
    return view_func(request, *args, **kwargs)
  File "/Anty/main/Anty/views/listing.py", line 69, in listing_detail
    return redirect("")
  File "/usr/local/lib/python3.8/dist-packages/django/shortcuts.py", line 41, in redirect
    return redirect_class(resolve_url(to, *args, **kwargs))
  File "/usr/local/lib/python3.8/dist-packages/django/shortcuts.py", line 130, in resolve_url
    return reverse(to, args=args, kwargs=kwargs)
  File "/usr/local/lib/python3.8/dist-packages/django/urls/base.py", line 86, in reverse
    return resolver._reverse_with_prefix(view, prefix, *args, **kwargs)
  File "/usr/local/lib/python3.8/dist-packages/django/urls/resolvers.py", line 694, in _reverse_with_prefix
    raise NoReverseMatch(msg)
django.urls.exceptions.NoReverseMatch: Reverse for '' not found. '' is not a valid view function or pattern name.
INFO:django.utils.autoreload:/Anty/main/Anty/views/listing.py changed, reloading.
INFO:django.utils.autoreload:/Anty/main/Anty/views/listing.py changed, reloading.
ERROR:django.request:Internal Server Error: /listing_detail/
Traceback (most recent call last):
  File "/usr/local/lib/python3.8/dist-packages/django/core/handlers/exception.py", line 47, in inner
    response = get_response(request)
  File "/usr/local/lib/python3.8/dist-packages/django/core/handlers/base.py", line 181, in _get_response
    response = wrapped_callback(request, *callback_args, **callback_kwargs)
  File "/usr/local/lib/python3.8/dist-packages/django/contrib/auth/decorators.py", line 21, in _wrapped_view
    return view_func(request, *args, **kwargs)
  File "/Anty/main/Anty/views/listing.py", line 70, in listing_detail
    media.uploadObject(os.path.join("/Anty/main/",file_name), "/service/image/temporary/")
NameError: name 'os' is not defined
INFO:django.utils.autoreload:/Anty/main/Anty/views/listing.py changed, reloading.
ERROR:django.request:Internal Server Error: /listing_detail/
Traceback (most recent call last):
  File "/usr/local/lib/python3.8/dist-packages/django/core/handlers/exception.py", line 47, in inner
    response = get_response(request)
  File "/usr/local/lib/python3.8/dist-packages/django/core/handlers/base.py", line 181, in _get_response
    response = wrapped_callback(request, *callback_args, **callback_kwargs)
  File "/usr/local/lib/python3.8/dist-packages/django/contrib/auth/decorators.py", line 21, in _wrapped_view
    return view_func(request, *args, **kwargs)
  File "/Anty/main/Anty/views/listing.py", line 71, in listing_detail
    media.uploadObject(os.path.join("/Anty/main/",file_name), "/service/image/temporary/")
NameError: name 'os' is not defined
INFO:django.utils.autoreload:/Anty/main/Anty/views/listing.py changed, reloading.
ERROR:django.request:Internal Server Error: /listing_detail/
Traceback (most recent call last):
  File "/usr/local/lib/python3.8/dist-packages/django/core/handlers/exception.py", line 47, in inner
    response = get_response(request)
  File "/usr/local/lib/python3.8/dist-packages/django/core/handlers/base.py", line 181, in _get_response
    response = wrapped_callback(request, *callback_args, **callback_kwargs)
  File "/usr/local/lib/python3.8/dist-packages/django/contrib/auth/decorators.py", line 21, in _wrapped_view
    return view_func(request, *args, **kwargs)
  File "/Anty/main/Anty/views/listing.py", line 71, in listing_detail
    media.uploadObject(os.path.join("/Anty/main/",file_name), "/service/image/temporary/")
  File "/Anty/main/Anty/util/media.py", line 38, in uploadObject
    with open(media_path, 'rb') as image:
FileNotFoundError: [Errno 2] No such file or directory: '/Anty/main/temporary_image/1_1634379067.6820908.jpg'
WARNING:django.request:Not Found: /images/iconmonstr-help-2-240 1.png
WARNING:django.request:Not Found: /images/iconmonstr-help-2-240 1.png
ERROR:django.request:Internal Server Error: /listing_detail/
Traceback (most recent call last):
  File "/usr/local/lib/python3.8/dist-packages/django/core/handlers/exception.py", line 47, in inner
    response = get_response(request)
  File "/usr/local/lib/python3.8/dist-packages/django/core/handlers/base.py", line 181, in _get_response
    response = wrapped_callback(request, *callback_args, **callback_kwargs)
  File "/usr/local/lib/python3.8/dist-packages/django/contrib/auth/decorators.py", line 21, in _wrapped_view
    return view_func(request, *args, **kwargs)
  File "/Anty/main/Anty/views/listing.py", line 71, in listing_detail
    media.uploadObject(os.path.join("/Anty/main/",file_name), "/service/image/temporary/")
  File "/Anty/main/Anty/util/media.py", line 38, in uploadObject
    with open(media_path, 'rb') as image:
FileNotFoundError: [Errno 2] No such file or directory: '/Anty/main/temporary_image/1_1634379119.6391294.jpg'
INFO:django.utils.autoreload:/Anty/main/Anty/views/listing.py changed, reloading.
ERROR:django.request:Internal Server Error: /listing_detail/
Traceback (most recent call last):
  File "/usr/local/lib/python3.8/dist-packages/django/core/handlers/exception.py", line 47, in inner
    response = get_response(request)
  File "/usr/local/lib/python3.8/dist-packages/django/core/handlers/base.py", line 181, in _get_response
    response = wrapped_callback(request, *callback_args, **callback_kwargs)
  File "/usr/local/lib/python3.8/dist-packages/django/contrib/auth/decorators.py", line 21, in _wrapped_view
    return view_func(request, *args, **kwargs)
  File "/Anty/main/Anty/views/listing.py", line 75, in listing_detail
    return render(request, template_name, params)
  File "/usr/local/lib/python3.8/dist-packages/django/shortcuts.py", line 19, in render
    content = loader.render_to_string(template_name, context, request, using=using)
  File "/usr/local/lib/python3.8/dist-packages/django/template/loader.py", line 61, in render_to_string
    template = get_template(template_name, using=using)
  File "/usr/local/lib/python3.8/dist-packages/django/template/loader.py", line 19, in get_template
    raise TemplateDoesNotExist(template_name, chain=chain)
django.template.exceptions.TemplateDoesNotExist: listing/comfirm.html
INFO:django.utils.autoreload:/Anty/main/Anty/views/listing.py changed, reloading.
ERROR:django.security.SuspiciousFileOperation:The joined path (/Anty/main/temporary_image/1_1634379230.290066.jpg) is located outside of the base path component (/Anty/main/media)
WARNING:django.request:Bad Request: /listing_detail/
INFO:django.utils.autoreload:/Anty/main/Anty/views/listing.py changed, reloading.
WARNING:django.request:Not Found: /images/iconmonstr-help-2-240 1.png
ERROR:django.request:Internal Server Error: /listing_detail/
Traceback (most recent call last):
  File "/usr/local/lib/python3.8/dist-packages/django/core/handlers/exception.py", line 47, in inner
    response = get_response(request)
  File "/usr/local/lib/python3.8/dist-packages/django/core/handlers/base.py", line 181, in _get_response
    response = wrapped_callback(request, *callback_args, **callback_kwargs)
  File "/usr/local/lib/python3.8/dist-packages/django/contrib/auth/decorators.py", line 21, in _wrapped_view
    return view_func(request, *args, **kwargs)
  File "/Anty/main/Anty/views/listing.py", line 75, in listing_detail
    return render(request, template_name, params)
  File "/usr/local/lib/python3.8/dist-packages/django/shortcuts.py", line 19, in render
    content = loader.render_to_string(template_name, context, request, using=using)
  File "/usr/local/lib/python3.8/dist-packages/django/template/loader.py", line 61, in render_to_string
    template = get_template(template_name, using=using)
  File "/usr/local/lib/python3.8/dist-packages/django/template/loader.py", line 19, in get_template
    raise TemplateDoesNotExist(template_name, chain=chain)
django.template.exceptions.TemplateDoesNotExist: listing/comfirm.html
ERROR:django.request:Internal Server Error: /listing_detail/
Traceback (most recent call last):
  File "/usr/local/lib/python3.8/dist-packages/django/core/handlers/exception.py", line 47, in inner
    response = get_response(request)
  File "/usr/local/lib/python3.8/dist-packages/django/core/handlers/base.py", line 181, in _get_response
    response = wrapped_callback(request, *callback_args, **callback_kwargs)
  File "/usr/local/lib/python3.8/dist-packages/django/contrib/auth/decorators.py", line 21, in _wrapped_view
    return view_func(request, *args, **kwargs)
  File "/Anty/main/Anty/views/listing.py", line 75, in listing_detail
    return render(request, template_name, params)
  File "/usr/local/lib/python3.8/dist-packages/django/shortcuts.py", line 19, in render
    content = loader.render_to_string(template_name, context, request, using=using)
  File "/usr/local/lib/python3.8/dist-packages/django/template/loader.py", line 61, in render_to_string
    template = get_template(template_name, using=using)
  File "/usr/local/lib/python3.8/dist-packages/django/template/loader.py", line 19, in get_template
    raise TemplateDoesNotExist(template_name, chain=chain)
django.template.exceptions.TemplateDoesNotExist: listing/comfirm.html
ERROR:django.request:Internal Server Error: /listing_detail/
Traceback (most recent call last):
  File "/usr/local/lib/python3.8/dist-packages/django/core/handlers/exception.py", line 47, in inner
    response = get_response(request)
  File "/usr/local/lib/python3.8/dist-packages/django/core/handlers/base.py", line 181, in _get_response
    response = wrapped_callback(request, *callback_args, **callback_kwargs)
  File "/usr/local/lib/python3.8/dist-packages/django/contrib/auth/decorators.py", line 21, in _wrapped_view
    return view_func(request, *args, **kwargs)
  File "/Anty/main/Anty/views/listing.py", line 75, in listing_detail
    return render(request, template_name, params)
  File "/usr/local/lib/python3.8/dist-packages/django/shortcuts.py", line 19, in render
    content = loader.render_to_string(template_name, context, request, using=using)
  File "/usr/local/lib/python3.8/dist-packages/django/template/loader.py", line 61, in render_to_string
    template = get_template(template_name, using=using)
  File "/usr/local/lib/python3.8/dist-packages/django/template/loader.py", line 19, in get_template
    raise TemplateDoesNotExist(template_name, chain=chain)
django.template.exceptions.TemplateDoesNotExist: listing/comfirm.html
INFO:django.utils.autoreload:/Anty/main/Anty/util/media.py changed, reloading.
ERROR:django.request:Internal Server Error: /listing_detail/
Traceback (most recent call last):
  File "/usr/local/lib/python3.8/dist-packages/django/core/handlers/exception.py", line 47, in inner
    response = get_response(request)
  File "/usr/local/lib/python3.8/dist-packages/django/core/handlers/base.py", line 181, in _get_response
    response = wrapped_callback(request, *callback_args, **callback_kwargs)
  File "/usr/local/lib/python3.8/dist-packages/django/contrib/auth/decorators.py", line 21, in _wrapped_view
    return view_func(request, *args, **kwargs)
  File "/Anty/main/Anty/views/listing.py", line 71, in listing_detail
    media.uploadObject(os.path.join("/Anty/main/media/",file_name), "/service/image/temporary/")
  File "/Anty/main/Anty/util/media.py", line 40, in uploadObject
    print (respobse)
NameError: name 'respobse' is not defined
INFO:django.utils.autoreload:/Anty/main/Anty/util/media.py changed, reloading.
ERROR:django.request:Internal Server Error: /listing_detail/
Traceback (most recent call last):
  File "/usr/local/lib/python3.8/dist-packages/django/core/handlers/exception.py", line 47, in inner
    response = get_response(request)
  File "/usr/local/lib/python3.8/dist-packages/django/core/handlers/base.py", line 181, in _get_response
    response = wrapped_callback(request, *callback_args, **callback_kwargs)
  File "/usr/local/lib/python3.8/dist-packages/django/contrib/auth/decorators.py", line 21, in _wrapped_view
    return view_func(request, *args, **kwargs)
  File "/Anty/main/Anty/views/listing.py", line 75, in listing_detail
    return render(request, template_name, params)
  File "/usr/local/lib/python3.8/dist-packages/django/shortcuts.py", line 19, in render
    content = loader.render_to_string(template_name, context, request, using=using)
  File "/usr/local/lib/python3.8/dist-packages/django/template/loader.py", line 61, in render_to_string
    template = get_template(template_name, using=using)
  File "/usr/local/lib/python3.8/dist-packages/django/template/loader.py", line 19, in get_template
    raise TemplateDoesNotExist(template_name, chain=chain)
django.template.exceptions.TemplateDoesNotExist: listing/comfirm.html
INFO:django.utils.autoreload:/Anty/main/Anty/util/media.py changed, reloading.
ERROR:django.request:Internal Server Error: /listing_detail/
Traceback (most recent call last):
  File "/usr/local/lib/python3.8/dist-packages/django/core/handlers/exception.py", line 47, in inner
    response = get_response(request)
  File "/usr/local/lib/python3.8/dist-packages/django/core/handlers/base.py", line 181, in _get_response
    response = wrapped_callback(request, *callback_args, **callback_kwargs)
  File "/usr/local/lib/python3.8/dist-packages/django/contrib/auth/decorators.py", line 21, in _wrapped_view
    return view_func(request, *args, **kwargs)
  File "/Anty/main/Anty/views/listing.py", line 75, in listing_detail
    return render(request, template_name, params)
  File "/usr/local/lib/python3.8/dist-packages/django/shortcuts.py", line 19, in render
    content = loader.render_to_string(template_name, context, request, using=using)
  File "/usr/local/lib/python3.8/dist-packages/django/template/loader.py", line 61, in render_to_string
    template = get_template(template_name, using=using)
  File "/usr/local/lib/python3.8/dist-packages/django/template/loader.py", line 19, in get_template
    raise TemplateDoesNotExist(template_name, chain=chain)
django.template.exceptions.TemplateDoesNotExist: listing/comfirm.html
INFO:django.utils.autoreload:/Anty/main/Anty/util/media.py changed, reloading.
ERROR:django.request:Internal Server Error: /listing_detail/
Traceback (most recent call last):
  File "/usr/local/lib/python3.8/dist-packages/django/core/handlers/exception.py", line 47, in inner
    response = get_response(request)
  File "/usr/local/lib/python3.8/dist-packages/django/core/handlers/base.py", line 181, in _get_response
    response = wrapped_callback(request, *callback_args, **callback_kwargs)
  File "/usr/local/lib/python3.8/dist-packages/django/contrib/auth/decorators.py", line 21, in _wrapped_view
    return view_func(request, *args, **kwargs)
  File "/Anty/main/Anty/views/listing.py", line 71, in listing_detail
    media.uploadObject(os.path.join("/Anty/main/media/",file_name), "/service/image/temporary/")
  File "/Anty/main/Anty/util/media.py", line 40, in uploadObject
    print (response.text())
TypeError: 'str' object is not callable
INFO:django.utils.autoreload:/Anty/main/Anty/util/media.py changed, reloading.
ERROR:django.request:Internal Server Error: /listing_detail/
Traceback (most recent call last):
  File "/usr/local/lib/python3.8/dist-packages/django/core/handlers/exception.py", line 47, in inner
    response = get_response(request)
  File "/usr/local/lib/python3.8/dist-packages/django/core/handlers/base.py", line 181, in _get_response
    response = wrapped_callback(request, *callback_args, **callback_kwargs)
  File "/usr/local/lib/python3.8/dist-packages/django/contrib/auth/decorators.py", line 21, in _wrapped_view
    return view_func(request, *args, **kwargs)
  File "/Anty/main/Anty/views/listing.py", line 75, in listing_detail
    return render(request, template_name, params)
  File "/usr/local/lib/python3.8/dist-packages/django/shortcuts.py", line 19, in render
    content = loader.render_to_string(template_name, context, request, using=using)
  File "/usr/local/lib/python3.8/dist-packages/django/template/loader.py", line 61, in render_to_string
    template = get_template(template_name, using=using)
  File "/usr/local/lib/python3.8/dist-packages/django/template/loader.py", line 19, in get_template
    raise TemplateDoesNotExist(template_name, chain=chain)
django.template.exceptions.TemplateDoesNotExist: listing/comfirm.html
INFO:django.utils.autoreload:/Anty/main/Anty/util/media.py changed, reloading.
ERROR:django.request:Internal Server Error: /listing_detail/
Traceback (most recent call last):
  File "/usr/local/lib/python3.8/dist-packages/django/core/handlers/exception.py", line 47, in inner
    response = get_response(request)
  File "/usr/local/lib/python3.8/dist-packages/django/core/handlers/base.py", line 181, in _get_response
    response = wrapped_callback(request, *callback_args, **callback_kwargs)
  File "/usr/local/lib/python3.8/dist-packages/django/contrib/auth/decorators.py", line 21, in _wrapped_view
    return view_func(request, *args, **kwargs)
  File "/Anty/main/Anty/views/listing.py", line 75, in listing_detail
    return render(request, template_name, params)
  File "/usr/local/lib/python3.8/dist-packages/django/shortcuts.py", line 19, in render
    content = loader.render_to_string(template_name, context, request, using=using)
  File "/usr/local/lib/python3.8/dist-packages/django/template/loader.py", line 61, in render_to_string
    template = get_template(template_name, using=using)
  File "/usr/local/lib/python3.8/dist-packages/django/template/loader.py", line 19, in get_template
    raise TemplateDoesNotExist(template_name, chain=chain)
django.template.exceptions.TemplateDoesNotExist: listing/comfirm.html
INFO:django.utils.autoreload:/Anty/main/Anty/views/listing.py changed, reloading.
ERROR:django.request:Internal Server Error: /listing_detail/
Traceback (most recent call last):
  File "/usr/local/lib/python3.8/dist-packages/django/core/handlers/exception.py", line 47, in inner
    response = get_response(request)
  File "/usr/local/lib/python3.8/dist-packages/django/core/handlers/base.py", line 181, in _get_response
    response = wrapped_callback(request, *callback_args, **callback_kwargs)
  File "/usr/local/lib/python3.8/dist-packages/django/contrib/auth/decorators.py", line 21, in _wrapped_view
    return view_func(request, *args, **kwargs)
  File "/Anty/main/Anty/views/listing.py", line 75, in listing_detail
    return render(request, template_name, params)
  File "/usr/local/lib/python3.8/dist-packages/django/shortcuts.py", line 19, in render
    content = loader.render_to_string(template_name, context, request, using=using)
  File "/usr/local/lib/python3.8/dist-packages/django/template/loader.py", line 61, in render_to_string
    template = get_template(template_name, using=using)
  File "/usr/local/lib/python3.8/dist-packages/django/template/loader.py", line 19, in get_template
    raise TemplateDoesNotExist(template_name, chain=chain)
django.template.exceptions.TemplateDoesNotExist: listing/comfirm.html
INFO:django.utils.autoreload:/Anty/main/Anty/views/listing.py changed, reloading.
ERROR:django.request:Internal Server Error: /listing_detail/
Traceback (most recent call last):
  File "/usr/local/lib/python3.8/dist-packages/django/core/handlers/exception.py", line 47, in inner
    response = get_response(request)
  File "/usr/local/lib/python3.8/dist-packages/django/core/handlers/base.py", line 181, in _get_response
    response = wrapped_callback(request, *callback_args, **callback_kwargs)
  File "/usr/local/lib/python3.8/dist-packages/django/contrib/auth/decorators.py", line 21, in _wrapped_view
    return view_func(request, *args, **kwargs)
  File "/Anty/main/Anty/views/listing.py", line 75, in listing_detail
    return render(request, template_name, params)
  File "/usr/local/lib/python3.8/dist-packages/django/shortcuts.py", line 19, in render
    content = loader.render_to_string(template_name, context, request, using=using)
  File "/usr/local/lib/python3.8/dist-packages/django/template/loader.py", line 61, in render_to_string
    template = get_template(template_name, using=using)
  File "/usr/local/lib/python3.8/dist-packages/django/template/loader.py", line 19, in get_template
    raise TemplateDoesNotExist(template_name, chain=chain)
django.template.exceptions.TemplateDoesNotExist: listing/comfirm.html
INFO:django.utils.autoreload:/Anty/main/Anty/util/media.py changed, reloading.
ERROR:django.request:Internal Server Error: /listing_detail/
Traceback (most recent call last):
  File "/usr/local/lib/python3.8/dist-packages/django/core/handlers/exception.py", line 47, in inner
    response = get_response(request)
  File "/usr/local/lib/python3.8/dist-packages/django/core/handlers/base.py", line 181, in _get_response
    response = wrapped_callback(request, *callback_args, **callback_kwargs)
  File "/usr/local/lib/python3.8/dist-packages/django/contrib/auth/decorators.py", line 21, in _wrapped_view
    return view_func(request, *args, **kwargs)
  File "/Anty/main/Anty/views/listing.py", line 75, in listing_detail
    return render(request, template_name, params)
  File "/usr/local/lib/python3.8/dist-packages/django/shortcuts.py", line 19, in render
    content = loader.render_to_string(template_name, context, request, using=using)
  File "/usr/local/lib/python3.8/dist-packages/django/template/loader.py", line 61, in render_to_string
    template = get_template(template_name, using=using)
  File "/usr/local/lib/python3.8/dist-packages/django/template/loader.py", line 19, in get_template
    raise TemplateDoesNotExist(template_name, chain=chain)
django.template.exceptions.TemplateDoesNotExist: listing/comfirm.html
INFO:django.utils.autoreload:/Anty/main/Anty/util/media.py changed, reloading.
ERROR:django.request:Internal Server Error: /listing_detail/
Traceback (most recent call last):
  File "/usr/local/lib/python3.8/dist-packages/django/core/handlers/exception.py", line 47, in inner
    response = get_response(request)
  File "/usr/local/lib/python3.8/dist-packages/django/core/handlers/base.py", line 181, in _get_response
    response = wrapped_callback(request, *callback_args, **callback_kwargs)
  File "/usr/local/lib/python3.8/dist-packages/django/contrib/auth/decorators.py", line 21, in _wrapped_view
    return view_func(request, *args, **kwargs)
  File "/Anty/main/Anty/views/listing.py", line 71, in listing_detail
    media.uploadObject(os.path.join("/Anty/main/media/",file_name), "/service/image/temporary/")
  File "/Anty/main/Anty/util/media.py", line 36, in uploadObject
    'X-Auth-Token': getToken().replace('\"', ''),  # tokenの取得
  File "/Anty/main/Anty/util/media.py", line 25, in getToken
    return json.dumps(data["access"]["token"]["id"], indent=4)
KeyError: 'access'
INFO:django.utils.autoreload:/Anty/main/Anty/util/media.py changed, reloading.
ERROR:django.request:Internal Server Error: /listing_detail/
Traceback (most recent call last):
  File "/usr/local/lib/python3.8/dist-packages/django/core/handlers/exception.py", line 47, in inner
    response = get_response(request)
  File "/usr/local/lib/python3.8/dist-packages/django/core/handlers/base.py", line 181, in _get_response
    response = wrapped_callback(request, *callback_args, **callback_kwargs)
  File "/usr/local/lib/python3.8/dist-packages/django/contrib/auth/decorators.py", line 21, in _wrapped_view
    return view_func(request, *args, **kwargs)
  File "/Anty/main/Anty/views/listing.py", line 75, in listing_detail
    return render(request, template_name, params)
  File "/usr/local/lib/python3.8/dist-packages/django/shortcuts.py", line 19, in render
    content = loader.render_to_string(template_name, context, request, using=using)
  File "/usr/local/lib/python3.8/dist-packages/django/template/loader.py", line 61, in render_to_string
    template = get_template(template_name, using=using)
  File "/usr/local/lib/python3.8/dist-packages/django/template/loader.py", line 19, in get_template
    raise TemplateDoesNotExist(template_name, chain=chain)
django.template.exceptions.TemplateDoesNotExist: listing/comfirm.html
INFO:django.utils.autoreload:/Anty/main/Anty/util/media.py changed, reloading.
ERROR:django.request:Internal Server Error: /listing_detail/
Traceback (most recent call last):
  File "/usr/local/lib/python3.8/dist-packages/django/core/handlers/exception.py", line 47, in inner
    response = get_response(request)
  File "/usr/local/lib/python3.8/dist-packages/django/core/handlers/base.py", line 181, in _get_response
    response = wrapped_callback(request, *callback_args, **callback_kwargs)
  File "/usr/local/lib/python3.8/dist-packages/django/contrib/auth/decorators.py", line 21, in _wrapped_view
    return view_func(request, *args, **kwargs)
  File "/Anty/main/Anty/views/listing.py", line 75, in listing_detail
    return render(request, template_name, params)
  File "/usr/local/lib/python3.8/dist-packages/django/shortcuts.py", line 19, in render
    content = loader.render_to_string(template_name, context, request, using=using)
  File "/usr/local/lib/python3.8/dist-packages/django/template/loader.py", line 61, in render_to_string
    template = get_template(template_name, using=using)
  File "/usr/local/lib/python3.8/dist-packages/django/template/loader.py", line 19, in get_template
    raise TemplateDoesNotExist(template_name, chain=chain)
django.template.exceptions.TemplateDoesNotExist: listing/comfirm.html
INFO:django.utils.autoreload:/Anty/main/Anty/views/listing.py changed, reloading.
ERROR:django.request:Internal Server Error: /listing_detail/
Traceback (most recent call last):
  File "/usr/local/lib/python3.8/dist-packages/django/core/handlers/exception.py", line 47, in inner
    response = get_response(request)
  File "/usr/local/lib/python3.8/dist-packages/django/core/handlers/base.py", line 181, in _get_response
    response = wrapped_callback(request, *callback_args, **callback_kwargs)
  File "/usr/local/lib/python3.8/dist-packages/django/contrib/auth/decorators.py", line 21, in _wrapped_view
    return view_func(request, *args, **kwargs)
  File "/Anty/main/Anty/views/listing.py", line 75, in listing_detail
    return render(request, template_name, params)
  File "/usr/local/lib/python3.8/dist-packages/django/shortcuts.py", line 19, in render
    content = loader.render_to_string(template_name, context, request, using=using)
  File "/usr/local/lib/python3.8/dist-packages/django/template/loader.py", line 61, in render_to_string
    template = get_template(template_name, using=using)
  File "/usr/local/lib/python3.8/dist-packages/django/template/loader.py", line 19, in get_template
    raise TemplateDoesNotExist(template_name, chain=chain)
django.template.exceptions.TemplateDoesNotExist: listing/comfirm.html
INFO:django.utils.autoreload:/Anty/main/Anty/views/listing.py changed, reloading.
ERROR:django.request:Internal Server Error: /listing_detail/
Traceback (most recent call last):
  File "/usr/local/lib/python3.8/dist-packages/django/core/handlers/exception.py", line 47, in inner
    response = get_response(request)
  File "/usr/local/lib/python3.8/dist-packages/django/core/handlers/base.py", line 181, in _get_response
    response = wrapped_callback(request, *callback_args, **callback_kwargs)
  File "/usr/local/lib/python3.8/dist-packages/django/contrib/auth/decorators.py", line 21, in _wrapped_view
    return view_func(request, *args, **kwargs)
  File "/Anty/main/Anty/views/listing.py", line 71, in listing_detail
    media.uploadObject(file_name, os.path.join("/Anty/main/media/",file_name), "/service/image/listing_temporary/")
TypeError: uploadObject() takes 2 positional arguments but 3 were given
INFO:django.utils.autoreload:/Anty/main/Anty/util/media.py changed, reloading.
ERROR:django.request:Internal Server Error: /listing_detail/
Traceback (most recent call last):
  File "/usr/local/lib/python3.8/dist-packages/django/core/handlers/exception.py", line 47, in inner
    response = get_response(request)
  File "/usr/local/lib/python3.8/dist-packages/django/core/handlers/base.py", line 181, in _get_response
    response = wrapped_callback(request, *callback_args, **callback_kwargs)
  File "/usr/local/lib/python3.8/dist-packages/django/contrib/auth/decorators.py", line 21, in _wrapped_view
    return view_func(request, *args, **kwargs)
  File "/Anty/main/Anty/views/listing.py", line 71, in listing_detail
    media.uploadObject(file_name, os.path.join("/Anty/main/media/",file_name), "/service/image/listing_temporary/")
  File "/Anty/main/Anty/util/media.py", line 40, in uploadObject
    response = requests.put(OBJECT_STORAGE + storage_path + file_nmae, headers=headers, data=image)
NameError: name 'file_nmae' is not defined
INFO:django.utils.autoreload:/Anty/main/Anty/util/media.py changed, reloading.
ERROR:django.request:Internal Server Error: /listing_detail/
Traceback (most recent call last):
  File "/usr/local/lib/python3.8/dist-packages/django/core/handlers/exception.py", line 47, in inner
    response = get_response(request)
  File "/usr/local/lib/python3.8/dist-packages/django/core/handlers/base.py", line 181, in _get_response
    response = wrapped_callback(request, *callback_args, **callback_kwargs)
  File "/usr/local/lib/python3.8/dist-packages/django/contrib/auth/decorators.py", line 21, in _wrapped_view
    return view_func(request, *args, **kwargs)
  File "/Anty/main/Anty/views/listing.py", line 75, in listing_detail
    return render(request, template_name, params)
  File "/usr/local/lib/python3.8/dist-packages/django/shortcuts.py", line 19, in render
    content = loader.render_to_string(template_name, context, request, using=using)
  File "/usr/local/lib/python3.8/dist-packages/django/template/loader.py", line 61, in render_to_string
    template = get_template(template_name, using=using)
  File "/usr/local/lib/python3.8/dist-packages/django/template/loader.py", line 19, in get_template
    raise TemplateDoesNotExist(template_name, chain=chain)
django.template.exceptions.TemplateDoesNotExist: listing/comfirm.html
INFO:django.utils.autoreload:/Anty/main/Anty/views/listing.py changed, reloading.
INFO:django.utils.autoreload:/Anty/main/Anty/views/listing.py changed, reloading.
ERROR:django.request:Internal Server Error: /listing_detail/
Traceback (most recent call last):
  File "/usr/local/lib/python3.8/dist-packages/django/core/handlers/exception.py", line 47, in inner
    response = get_response(request)
  File "/usr/local/lib/python3.8/dist-packages/django/core/handlers/base.py", line 181, in _get_response
    response = wrapped_callback(request, *callback_args, **callback_kwargs)
  File "/usr/local/lib/python3.8/dist-packages/django/contrib/auth/decorators.py", line 21, in _wrapped_view
    return view_func(request, *args, **kwargs)
  File "/Anty/main/Anty/views/listing.py", line 75, in listing_detail
    return render(request, template_name, params)
  File "/usr/local/lib/python3.8/dist-packages/django/shortcuts.py", line 19, in render
    content = loader.render_to_string(template_name, context, request, using=using)
  File "/usr/local/lib/python3.8/dist-packages/django/template/loader.py", line 61, in render_to_string
    template = get_template(template_name, using=using)
  File "/usr/local/lib/python3.8/dist-packages/django/template/loader.py", line 19, in get_template
    raise TemplateDoesNotExist(template_name, chain=chain)
django.template.exceptions.TemplateDoesNotExist: listing/comfirm.html
INFO:django.utils.autoreload:/Anty/main/Anty/views/listing.py changed, reloading.
INFO:django.utils.autoreload:/Anty/main/Anty/views/listing.py changed, reloading.
INFO:django.utils.autoreload:/Anty/main/Anty/views/listing.py changed, reloading.
WARNING:django.request:Not Found: /HNAP1/
WARNING:django.request:Not Found: /select_category/}
INFO:django.utils.autoreload:/Anty/main/Anty/views/listing.py changed, reloading.
INFO:django.utils.autoreload:/Anty/main/Anty/views/listing.py changed, reloading.
WARNING:django.request:Not Found: /js/slick.js
WARNING:django.request:Not Found: /js/index.js
ERROR:django.request:Internal Server Error: /listing_detail/
Traceback (most recent call last):
  File "/usr/local/lib/python3.8/dist-packages/django/core/handlers/exception.py", line 47, in inner
    response = get_response(request)
  File "/usr/local/lib/python3.8/dist-packages/django/core/handlers/base.py", line 181, in _get_response
    response = wrapped_callback(request, *callback_args, **callback_kwargs)
  File "/usr/local/lib/python3.8/dist-packages/django/contrib/auth/decorators.py", line 21, in _wrapped_view
    return view_func(request, *args, **kwargs)
TypeError: listing_detail() missing 1 required positional argument: 'edit_data'
INFO:django.utils.autoreload:/Anty/main/Anty/views/listing.py changed, reloading.
WARNING:django.request:Not Found: /favicon.ico
WARNING:django.request:Not Found: /images/iconmonstr-help-2-240 1.png
WARNING:django.request:Not Found: /images/iconmonstr-help-2-240 1.png
WARNING:django.request:Not Found: /images/iconmonstr-help-2-240 1.png
INFO:django.utils.autoreload:/Anty/main/Anty/views/listing.py changed, reloading.
INFO:django.utils.autoreload:/Anty/main/Anty/views/listing.py changed, reloading.
INFO:django.utils.autoreload:/Anty/main/Anty/views/listing.py changed, reloading.
INFO:django.utils.autoreload:/Anty/main/Anty/views/listing.py changed, reloading.
INFO:django.utils.autoreload:/Anty/main/Anty/views/listing.py changed, reloading.
WARNING:django.request:Not Found: /images/iconmonstr-help-2-240 1.png
WARNING:django.request:Not Found: /images/iconmonstr-help-2-240 1.png
WARNING:django.request:Not Found: /images/iconmonstr-help-2-240 1.png
WARNING:django.request:Not Found: /images/iconmonstr-help-2-240 1.png
WARNING:django.request:Not Found: /images/58B0B7AF-548C-4480-8719-E84D93547D15.png
WARNING:django.request:Not Found: /images/58B0B7AF-548C-4480-8719-E84D93547D15.png
WARNING:django.request:Not Found: /images/58B0B7AF-548C-4480-8719-E84D93547D15.png
INFO:django.utils.autoreload:/Anty/main/Anty/views/listing.py changed, reloading.
WARNING:django.request:Not Found: /images/58B0B7AF-548C-4480-8719-E84D93547D15.png
WARNING:django.request:Not Found: /images/58B0B7AF-548C-4480-8719-E84D93547D15.png
WARNING:django.request:Not Found: /images/58B0B7AF-548C-4480-8719-E84D93547D15.png
ERROR:django.request:Internal Server Error: /listing_detail/
Traceback (most recent call last):
  File "/usr/local/lib/python3.8/dist-packages/django/core/handlers/exception.py", line 47, in inner
    response = get_response(request)
  File "/usr/local/lib/python3.8/dist-packages/django/core/handlers/base.py", line 181, in _get_response
    response = wrapped_callback(request, *callback_args, **callback_kwargs)
  File "/usr/local/lib/python3.8/dist-packages/django/contrib/auth/decorators.py", line 21, in _wrapped_view
    return view_func(request, *args, **kwargs)
  File "/Anty/main/Anty/views/listing.py", line 85, in listing_detail
    return render(request, template_name, params)
  File "/usr/local/lib/python3.8/dist-packages/django/shortcuts.py", line 19, in render
    content = loader.render_to_string(template_name, context, request, using=using)
  File "/usr/local/lib/python3.8/dist-packages/django/template/loader.py", line 61, in render_to_string
    template = get_template(template_name, using=using)
  File "/usr/local/lib/python3.8/dist-packages/django/template/loader.py", line 15, in get_template
    return engine.get_template(template_name)
  File "/usr/local/lib/python3.8/dist-packages/django/template/backends/django.py", line 34, in get_template
    return Template(self.engine.get_template(template_name), self)
  File "/usr/local/lib/python3.8/dist-packages/django/template/engine.py", line 143, in get_template
    template, origin = self.find_template(template_name)
  File "/usr/local/lib/python3.8/dist-packages/django/template/engine.py", line 125, in find_template
    template = loader.get_template(name, skip=skip)
  File "/usr/local/lib/python3.8/dist-packages/django/template/loaders/base.py", line 29, in get_template
    return Template(
  File "/usr/local/lib/python3.8/dist-packages/django/template/base.py", line 155, in __init__
    self.nodelist = self.compile_nodelist()
  File "/usr/local/lib/python3.8/dist-packages/django/template/base.py", line 193, in compile_nodelist
    return parser.parse()
  File "/usr/local/lib/python3.8/dist-packages/django/template/base.py", line 449, in parse
    raise self.error(token, e)
  File "/usr/local/lib/python3.8/dist-packages/django/template/base.py", line 447, in parse
    filter_expression = self.compile_filter(token.contents)
  File "/usr/local/lib/python3.8/dist-packages/django/template/base.py", line 563, in compile_filter
    return FilterExpression(token, self)
  File "/usr/local/lib/python3.8/dist-packages/django/template/base.py", line 662, in __init__
    raise TemplateSyntaxError("Could not parse the remainder: '%s' "
django.template.exceptions.TemplateSyntaxError: Could not parse the remainder: '[1]' from 'images[1]'
WARNING:django.request:Not Found: /images/iconmonstr-help-2-240 1.png
INFO:django.utils.autoreload:/Anty/main/Anty/views/listing.py changed, reloading.
WARNING:django.request:Not Found: /home.html
WARNING:django.request:Not Found: /js/slick.js
WARNING:django.request:Not Found: /js/index.js
ERROR:django.request:Internal Server Error: /admin
Traceback (most recent call last):
  File "/usr/local/lib/python3.8/dist-packages/django/core/handlers/exception.py", line 47, in inner
    response = get_response(request)
  File "/usr/local/lib/python3.8/dist-packages/django/utils/deprecation.py", line 116, in __call__
    response = self.process_request(request)
  File "/usr/local/lib/python3.8/dist-packages/django/middleware/common.py", line 54, in process_request
    path = self.get_full_path_with_slash(request)
  File "/usr/local/lib/python3.8/dist-packages/django/middleware/common.py", line 88, in get_full_path_with_slash
    raise RuntimeError(
RuntimeError: You called this URL via POST, but the URL doesn't end in a slash and you have APPEND_SLASH set. Django can't redirect to the slash URL while maintaining POST data. Change your form to point to 160.251.51.99:8000/admin/ (note the trailing slash), or set APPEND_SLASH=False in your Django settings.
WARNING:django.request:Not Found: /.env
WARNING:django.request:Not Found: /favicon.ico
WARNING:django.request:Not Found: /js/slick.js
WARNING:django.request:Not Found: /js/index.js
INFO:django.utils.autoreload:/Anty/main/main/urls.py changed, reloading.
ERROR:django.request:Internal Server Error: /listing_detail/
Traceback (most recent call last):
  File "/usr/local/lib/python3.8/dist-packages/django/core/handlers/exception.py", line 47, in inner
    response = get_response(request)
  File "/usr/local/lib/python3.8/dist-packages/django/core/handlers/base.py", line 181, in _get_response
    response = wrapped_callback(request, *callback_args, **callback_kwargs)
  File "/usr/local/lib/python3.8/dist-packages/django/contrib/auth/decorators.py", line 21, in _wrapped_view
    return view_func(request, *args, **kwargs)
  File "/Anty/main/Anty/views/listing.py", line 86, in listing_detail
    return render(request, template_name, params)
  File "/usr/local/lib/python3.8/dist-packages/django/shortcuts.py", line 19, in render
    content = loader.render_to_string(template_name, context, request, using=using)
  File "/usr/local/lib/python3.8/dist-packages/django/template/loader.py", line 62, in render_to_string
    return template.render(context, request)
  File "/usr/local/lib/python3.8/dist-packages/django/template/backends/django.py", line 61, in render
    return self.template.render(context)
  File "/usr/local/lib/python3.8/dist-packages/django/template/base.py", line 170, in render
    return self._render(context)
  File "/usr/local/lib/python3.8/dist-packages/django/template/base.py", line 162, in _render
    return self.nodelist.render(context)
  File "/usr/local/lib/python3.8/dist-packages/django/template/base.py", line 938, in render
    bit = node.render_annotated(context)
  File "/usr/local/lib/python3.8/dist-packages/django/template/base.py", line 905, in render_annotated
    return self.render(context)
  File "/usr/local/lib/python3.8/dist-packages/django/template/defaulttags.py", line 446, in render
    url = reverse(view_name, args=args, kwargs=kwargs, current_app=current_app)
  File "/usr/local/lib/python3.8/dist-packages/django/urls/base.py", line 86, in reverse
    return resolver._reverse_with_prefix(view, prefix, *args, **kwargs)
  File "/usr/local/lib/python3.8/dist-packages/django/urls/resolvers.py", line 694, in _reverse_with_prefix
    raise NoReverseMatch(msg)
django.urls.exceptions.NoReverseMatch: Reverse for 'listing' not found. 'listing' is not a valid view function or pattern name.
INFO:django.utils.autoreload:/Anty/main/main/urls.py changed, reloading.
WARNING:django.request:Not Found: /config/getuser
WARNING:django.request:Not Found: /config/getuser
